{"active":1696979001249,"date":-1696978980975,"event":"draft","input":"how can i increase the number of topics generated\n\n","sender_id":"d9218c0f-616b-453d-85a3-dcbe9ee8ddba"}
{"active":1696980924964,"date":-1696980872278,"event":"draft","input":"Topic representation 'KeyBERT' not found.\n\n","sender_id":"d9218c0f-616b-453d-85a3-dcbe9ee8ddba"}
{"active":1696986541690,"date":-1696986523549,"event":"draft","input":"i want to save the output of this into a csv file\n","sender_id":"d9218c0f-616b-453d-85a3-dcbe9ee8ddba"}
{"active":1696986621240,"date":-1696986606110,"event":"draft","input":"i want to save this as a csv\n","sender_id":"d9218c0f-616b-453d-85a3-dcbe9ee8ddba"}
{"active":1697048513119,"date":-1697048481333,"event":"draft","input":"what format should the model recieve the data in\n\n","sender_id":"d9218c0f-616b-453d-85a3-dcbe9ee8ddba"}
{"active":1698285118179,"date":-1698285081162,"event":"draft","input":"how should i change it to using cosine metric\n\n","sender_id":"d9218c0f-616b-453d-85a3-dcbe9ee8ddba"}
{"active":1698287755790,"date":-1698287734962,"event":"draft","input":"is there anyway to export this visual\n\n","sender_id":"d9218c0f-616b-453d-85a3-dcbe9ee8ddba"}
{"active":1698298396311,"date":-1698298382184,"event":"draft","input":"what if i want to save this to a csv file\n\n","sender_id":"d9218c0f-616b-453d-85a3-dcbe9ee8ddba"}
{"active":1698298398261,"date":0,"event":"draft","input":" ","sender_id":"d9218c0f-616b-453d-85a3-dcbe9ee8ddba"}
{"date":"2023-10-10T20:01:59.711Z","event":"chat","history":[{"author_id":"d9218c0f-616b-453d-85a3-dcbe9ee8ddba","content":"<span class=\"user-mention\" account-id=chatgpt>@ChatGPT</span> help me fix my code.\n\n<details><summary>Context</summary>\n\n\nI ran a cell in a Jupyter notebook.\n\nI received the following error:\n\n```python\n---------------------------------------------------------------------------\nModuleNotFoundError                       Traceback (most recent call last)\nCell In[2], line 1\n----> 1 from bertopic.representation import KeyBERTInspired\n      2 from bertopic.representation import PartOfSpeech\n      3 from bertopic.representation import MaximalMarginalRelevance\n\nModuleNotFoundError: No module named 'bertopic'\n```\n\n\nMy Jupyter notebook using the Python 3 (Ubuntu Linux) kernel contains:\n\n```python\nfrom bertopic.representation import KeyBERTInspired\nfrom bertopic.representation import PartOfSpeech\nfrom bertopic.representation import MaximalMarginalRelevance\nfrom sklearn.datasets import fetch_20newsgroups\n\n# Documents to train on\ndocs = fetch_20newsgroups(subset='all',  remove=('headers', 'footers', 'quotes'))['data']\n\n# The main representation of a topic\nmain_representation = KeyBERTInspired()\n\n# Additional ways of representing a topic\naspect_model1 = PartOfSpeech(\"en_core_web_sm\")\naspect_model2 = [KeyBERTInspired(top_n_words=30), MaximalMarginalRelevance(diversity=.5)]\n\n# Add all models together to be run in a single `fit`\nrepresentation_model = {\n   \"Main\": main_representation,\n   \"Aspect1\":  aspect_model1,\n   \"Aspect2\":  aspect_model2 \n}\ntopic_model = BERTopic(representation_model=representation_model).fit(docs)\n\n```\n\n\n\n</details>","date":"2023-10-10T20:01:59.711Z"}],"sender_id":"d9218c0f-616b-453d-85a3-dcbe9ee8ddba"}
{"date":"2023-10-10T20:01:59.718Z","event":"chat","generating":false,"history":[{"author_id":"chatgpt","content":"The error \"ModuleNotFoundError: No module named 'bertopic'\" indicates that the package `bertopic` is not installed in your Python environment.\n\nTo fix this issue, you need to install the `bertopic` package. \n\n","date":"2023-10-10T20:01:59.718Z"}],"reply_to":"2023-10-10T20:01:59.711Z","sender_id":"chatgpt"}
{"date":"2023-10-10T20:02:09.664Z","event":"chat","history":[{"author_id":"d9218c0f-616b-453d-85a3-dcbe9ee8ddba","content":"<span class=\"user-mention\" account-id=chatgpt>@ChatGPT</span> help me fix my code.\n\n<details><summary>Context</summary>\n\n\nI ran a cell in a Jupyter notebook.\n\nI received the following error:\n\n```python\n---------------------------------------------------------------------------\nModuleNotFoundError                       Traceback (most recent call last)\nCell In[2], line 1\n----> 1 from bertopic.representation import KeyBERTInspired\n      2 from bertopic.representation import PartOfSpeech\n      3 from bertopic.representation import MaximalMarginalRelevance\n\nModuleNotFoundError: No module named 'bertopic'\n```\n\n\nMy Jupyter notebook using the Python 3 (Ubuntu Linux) kernel contains:\n\n```python\nfrom bertopic.representation import KeyBERTInspired\nfrom bertopic.representation import PartOfSpeech\nfrom bertopic.representation import MaximalMarginalRelevance\nfrom sklearn.datasets import fetch_20newsgroups\n\n# Documents to train on\ndocs = fetch_20newsgroups(subset='all',  remove=('headers', 'footers', 'quotes'))['data']\n\n# The main representation of a topic\nmain_representation = KeyBERTInspired()\n\n# Additional ways of representing a topic\naspect_model1 = PartOfSpeech(\"en_core_web_sm\")\naspect_model2 = [KeyBERTInspired(top_n_words=30), MaximalMarginalRelevance(diversity=.5)]\n\n# Add all models together to be run in a single `fit`\nrepresentation_model = {\n   \"Main\": main_representation,\n   \"Aspect1\":  aspect_model1,\n   \"Aspect2\":  aspect_model2 \n}\ntopic_model = BERTopic(representation_model=representation_model).fit(docs)\n\n```\n\n\n\n</details>","date":"2023-10-10T20:02:09.664Z"}],"sender_id":"d9218c0f-616b-453d-85a3-dcbe9ee8ddba"}
{"date":"2023-10-10T20:02:09.670Z","event":"chat","generating":false,"history":[{"author_id":"chatgpt","content":"The error message indicates that the module 'bertopic' could not be found. To fix this, you need to install the 'bertopic' library in your CoCalc environment. You can do this by running the following command in a code cell:\n\n```python\n!pip install bertopic\n```\n\nAfter installing the 'bertopic' library, you should be able to import and use it without any issues.","date":"2023-10-10T20:02:09.670Z"}],"reply_to":"2023-10-10T20:02:09.664Z","sender_id":"chatgpt"}
{"date":"2023-10-10T20:05:13.760Z","event":"chat","history":[{"author_id":"d9218c0f-616b-453d-85a3-dcbe9ee8ddba","content":"<span class=\"user-mention\" account-id=chatgpt>@ChatGPT</span> help me fix my code.\n\n<details><summary>Context</summary>\n\n\nI ran a cell in a Jupyter notebook.\n\nI received the following error:\n\n```python\n  Cell In[3], line 1\n    python -m spacy download en_core_web_sm\n              ^\nSyntaxError: invalid syntax\n```\n\n\nMy Jupyter notebook using the Python 3 (Ubuntu Linux) kernel contains:\n\n```python\npython -m spacy download en_core_web_sm\n\n```\n\n\n\n</details>","date":"2023-10-10T20:05:13.760Z"}],"sender_id":"d9218c0f-616b-453d-85a3-dcbe9ee8ddba"}
{"date":"2023-10-10T20:05:13.766Z","event":"chat","generating":false,"history":[{"author_id":"chatgpt","content":"The error you encountered is a `SyntaxError` and it indicates that the line `python -m spacy download en_core_web_sm` is not valid Python syntax.\n\nTo fix this issue, you need to run this command in a terminal or command-line interface, rather than directly in a Jupyter notebook. \n\nTo run this command from a Jupyter notebook, you can use the `!` character at the beginning of the line to indicate that it is a shell command.\n\nReplace this line:\n\n```python\npython -m spacy download en_core_web_sm\n```\n\nwith:\n\n```python\n!python -m spacy download en_core_web_sm\n```\n\nThis should resolve the `SyntaxError` and allow you to download the required spaCy model.","date":"2023-10-10T20:05:13.766Z"}],"reply_to":"2023-10-10T20:05:13.760Z","sender_id":"chatgpt"}
{"date":"2023-10-10T20:42:57.669Z","event":"chat","history":[{"author_id":"d9218c0f-616b-453d-85a3-dcbe9ee8ddba","content":"<span class=\"user-mention\" account-id=chatgpt>@ChatGPT</span> help me fix my code.\n\n<details><summary>Context</summary>\n\n\nI ran a cell in a Jupyter notebook.\n\nI received the following error:\n\n```python\n---------------------------------------------------------------------------\nNameError                                 Traceback (most recent call last)\nCell In[4], line 1\n----> 1 train_requs , test_requs , train_labels , test_labels = train_test_split (\n      2 requirements , labels , random_state =500 , test_size =.2)\n\nNameError: name 'train_test_split' is not defined\n```\n\n\nMy Jupyter notebook using the Python 3 (Ubuntu Linux) kernel contains:\n\n```python\ntrain_requs , test_requs , train_labels , test_labels = train_test_split (\nrequirements , labels , random_state =500 , test_size =.2)\n```\n\n\n\n</details>","date":"2023-10-10T20:42:57.669Z"}],"sender_id":"d9218c0f-616b-453d-85a3-dcbe9ee8ddba"}
{"date":"2023-10-10T20:42:57.675Z","event":"chat","generating":false,"history":[{"author_id":"chatgpt","content":"The error message `NameError: name 'train_test_split' is not defined` is indicating that the function `train_test_split` is not recognized. \n\nYou can fix this error by adding the following line of code at the top of your Jupyter notebook:\n\n```python\nfrom sklearn.model_selection import train_test_split\n```\n\nThis will import the `train_test_split` function from the `sklearn.model_selection` module, allowing you to use it in your code.\n\nMake sure you have the necessary packages installed by running `!pip install scikit-learn` if needed.","date":"2023-10-10T20:42:57.675Z"}],"reply_to":"2023-10-10T20:42:57.669Z","sender_id":"chatgpt"}
{"date":"2023-10-10T20:47:11.173Z","event":"chat","history":[{"author_id":"d9218c0f-616b-453d-85a3-dcbe9ee8ddba","content":"<span class=\"user-mention\" account-id=chatgpt>@ChatGPT</span> help me fix my code.\n\n<details><summary>Context</summary>\n\n\nI ran a cell in a Jupyter notebook.\n\nI received the following error:\n\n```python\n---------------------------------------------------------------------------\nTypeError                                 Traceback (most recent call last)\nCell In[15], line 14\n     12 plt.ylabel('Probabilities')\n     13 plt.title(f'Topic Distribution for Document {document_index + 1}')\n---> 14 plt.xticks(document_topics)\n     15 plt.show()\n\nFile /usr/lib/python3/dist-packages/matplotlib/pyplot.py:1809, in xticks(ticks, labels, **kwargs)\n   1806         raise TypeError(\"xticks(): Parameter 'labels' can't be set \"\n   1807                         \"without setting 'ticks'\")\n   1808 else:\n-> 1809     locs = ax.set_xticks(ticks)\n   1811 if labels is None:\n   1812     labels = ax.get_xticklabels()\n\nFile /usr/lib/python3/dist-packages/matplotlib/axes/_base.py:75, in _axis_method_wrapper.__set_name__.<locals>.wrapper(self, *args, **kwargs)\n     74 def wrapper(self, *args, **kwargs):\n---> 75     return get_method(self)(*args, **kwargs)\n\nFile /usr/lib/python3/dist-packages/matplotlib/axis.py:1855, in Axis.set_ticks(self, ticks, labels, minor, **kwargs)\n   1829 def set_ticks(self, ticks, labels=None, *, minor=False, **kwargs):\n   1830     \"\"\"\n   1831     Set this Axis' tick locations and optionally labels.\n   1832 \n   (...)\n   1853     ticks.\n   1854     \"\"\"\n-> 1855     result = self._set_tick_locations(ticks, minor=minor)\n   1856     if labels is not None:\n   1857         self.set_ticklabels(labels, minor=minor, **kwargs)\n\nFile /usr/lib/python3/dist-packages/matplotlib/axis.py:1815, in Axis._set_tick_locations(self, ticks, minor)\n   1813     shared = [self]\n   1814 for axis in shared:\n-> 1815     if len(ticks) > 1:\n   1816         xleft, xright = axis.get_view_interval()\n   1817         if xright > xleft:\n\nTypeError: object of type 'numpy.int64' has no len()\n```\n\n\nMy Jupyter notebook using the Python 3 (Ubuntu Linux) kernel contains:\n\n```python\nimport matplotlib.pyplot as plt\n\n# Assuming you have already obtained 'topics' and 'probs' for a single document\ndocument_index = 0  # Choose the document you want to visualize\ndocument_topics = topics[document_index]\ndocument_probabilities = probs[document_index]\n\n# Create a bar plot for the topics and their probabilities\nplt.figure(figsize=(10, 6))\nplt.bar(document_topics, document_probabilities, color='skyblue')\nplt.xlabel('Topics')\nplt.ylabel('Probabilities')\nplt.title(f'Topic Distribution for Document {document_index + 1}')\nplt.xticks(document_topics)\nplt.show()\n\n```\n\n\n\n</details>","date":"2023-10-10T20:47:11.173Z"}],"sender_id":"d9218c0f-616b-453d-85a3-dcbe9ee8ddba"}
{"date":"2023-10-10T20:47:11.179Z","event":"chat","generating":false,"history":[{"author_id":"chatgpt","content":"The error is caused by the line `plt.xticks(document_topics)`. The `document_topics` variable is of type `numpy.int64`, which cannot be directly used as input for `plt.xticks()`. \n\nTo fix this, you can convert `document_topics` to a list or array before passing it to `plt.xticks()`. One way to do this is using the `.tolist()` method on the `numpy` array or using the `list()` function. Here's an updated version of the code:\n\n```python\nimport matplotlib.pyplot as plt\n\n# Assuming you have already obtained 'topics' and 'probs' for a single document\ndocument_index = 0  # Choose the document you want to visualize\ndocument_topics = topics[document_index]\ndocument_probabilities = probs[document_index]\n\n# Create a bar plot for the topics and their probabilities\nplt.figure(figsize=(10, 6))\nplt.bar(document_topics, document_probabilities, color='skyblue')\nplt.xlabel('Topics')\nplt.ylabel('Probabilities')\nplt.title(f'Topic Distribution for Document {document_index + 1}')\nplt.xticks(document_topics.tolist())  # Convert to list using .tolist() method\nplt.show()\n```\n\nWith this modification, the code should run without any errors.","date":"2023-10-10T20:47:11.179Z"}],"reply_to":"2023-10-10T20:47:11.173Z","sender_id":"chatgpt"}
{"date":"2023-10-10T20:48:20.043Z","event":"chat","history":[{"author_id":"d9218c0f-616b-453d-85a3-dcbe9ee8ddba","content":"<span class=\"user-mention\" account-id=chatgpt>@ChatGPT</span> help me fix my code.\n\n<details><summary>Context</summary>\n\n\nI ran a cell in a Jupyter notebook.\n\nI received the following error:\n\n```python\n---------------------------------------------------------------------------\nTypeError                                 Traceback (most recent call last)\nCell In[17], line 14\n     12 plt.ylabel('Probabilities')\n     13 plt.title(f'Topic Distribution for Document {document_index + 1}')\n---> 14 plt.xticks(document_topics.tolist())  # Convert to list using .tolist() method\n     15 plt.show()\n\nFile /usr/lib/python3/dist-packages/matplotlib/pyplot.py:1809, in xticks(ticks, labels, **kwargs)\n   1806         raise TypeError(\"xticks(): Parameter 'labels' can't be set \"\n   1807                         \"without setting 'ticks'\")\n   1808 else:\n-> 1809     locs = ax.set_xticks(ticks)\n   1811 if labels is None:\n   1812     labels = ax.get_xticklabels()\n\nFile /usr/lib/python3/dist-packages/matplotlib/axes/_base.py:75, in _axis_method_wrapper.__set_name__.<locals>.wrapper(self, *args, **kwargs)\n     74 def wrapper(self, *args, **kwargs):\n---> 75     return get_method(self)(*args, **kwargs)\n\nFile /usr/lib/python3/dist-packages/matplotlib/axis.py:1855, in Axis.set_ticks(self, ticks, labels, minor, **kwargs)\n   1829 def set_ticks(self, ticks, labels=None, *, minor=False, **kwargs):\n   1830     \"\"\"\n   1831     Set this Axis' tick locations and optionally labels.\n   1832 \n   (...)\n   1853     ticks.\n   1854     \"\"\"\n-> 1855     result = self._set_tick_locations(ticks, minor=minor)\n   1856     if labels is not None:\n   1857         self.set_ticklabels(labels, minor=minor, **kwargs)\n\nFile /usr/lib/python3/dist-packages/matplotlib/axis.py:1815, in Axis._set_tick_locations(self, ticks, minor)\n   1813     shared = [self]\n   1814 for axis in shared:\n-> 1815     if len(ticks) > 1:\n   1816         xleft, xright = axis.get_view_interval()\n   1817         if xright > xleft:\n\nTypeError: object of type 'int' has no len()\n```\n\n\nMy Jupyter notebook using the Python 3 (Ubuntu Linux) kernel contains:\n\n```python\nimport matplotlib.pyplot as plt\n\n# Assuming you have already obtained 'topics' and 'probs' for a single document\ndocument_index = 0  # Choose the document you want to visualize\ndocument_topics = topics[document_index]\ndocument_probabilities = probs[document_index]\n\n# Create a bar plot for the topics and their probabilities\nplt.figure(figsize=(10, 6))\nplt.bar(topics, probs, color='skyblue')\nplt.xlabel('Topics')\nplt.ylabel('Probabilities')\nplt.title(f'Topic Distribution for Document {document_index + 1}')\nplt.xticks(document_topics.tolist())  # Convert to list using .tolist() method\nplt.show()\n```\n\n\n\n</details>","date":"2023-10-10T20:48:20.043Z"}],"sender_id":"d9218c0f-616b-453d-85a3-dcbe9ee8ddba"}
{"date":"2023-10-10T20:48:20.049Z","event":"chat","generating":false,"history":[{"author_id":"chatgpt","content":"The error message indicates that the `document_topics` variable is an integer and does not have a length, which is causing the `TypeError` when trying to convert it to a list using the `.tolist()` method.\n\nTo fix the code, make sure that the `topics` variable is a list and not a single integer. If necessary, convert the `topics` variable to a list before assigning it to `document_topics`.\n\nHere's an updated code snippet:\n\n```python\n# Assuming you have already obtained 'topics' and 'probs' for a single document\ndocument_index = 0  # Choose the document you want to visualize\ndocument_topics = [topics[document_index]]\ndocument_probabilities = probs[document_index]\n\n# Create a bar plot for the topics and their probabilities\nplt.figure(figsize=(10, 6))\nplt.bar(document_topics, document_probabilities, color='skyblue')\nplt.xlabel('Topics')\nplt.ylabel('Probabilities')\nplt.title(f'Topic Distribution for Document {document_index + 1}')\nplt.xticks(document_topics)  # Remove .tolist() method\nplt.show()\n```\n\nMake sure to substitute the appropriate values for `topics` and `probs` in the code.","date":"2023-10-10T20:48:20.049Z"}],"reply_to":"2023-10-10T20:48:20.043Z","sender_id":"chatgpt"}
{"date":"2023-10-10T20:52:01.067Z","event":"chat","history":[{"author_id":"d9218c0f-616b-453d-85a3-dcbe9ee8ddba","content":"<span class=\"user-mention\" account-id=chatgpt>@ChatGPT</span> help me fix my code.\n\n<details><summary>Context</summary>\n\n\nI ran a cell in a Jupyter notebook.\n\nI received the following error:\n\n```python\n---------------------------------------------------------------------------\nValueError                                Traceback (most recent call last)\nCell In[22], line 22\n     19 document_probabilities = probs[document_index]\n     21 # Create a DataFrame for visualization\n---> 22 df = pd.DataFrame({'Topics': document_topics, 'Probabilities': document_probabilities})\n     24 # Create a horizontal bar plot using Seaborn\n     25 plt.figure(figsize=(10, 6))\n\nFile /usr/local/lib/python3.10/dist-packages/pandas/core/frame.py:709, in DataFrame.__init__(self, data, index, columns, dtype, copy)\n    703     mgr = self._init_mgr(\n    704         data, axes={\"index\": index, \"columns\": columns}, dtype=dtype, copy=copy\n    705     )\n    707 elif isinstance(data, dict):\n    708     # GH#38939 de facto copy defaults to False only in non-dict cases\n--> 709     mgr = dict_to_mgr(data, index, columns, dtype=dtype, copy=copy, typ=manager)\n    710 elif isinstance(data, ma.MaskedArray):\n    711     from numpy.ma import mrecords\n\nFile /usr/local/lib/python3.10/dist-packages/pandas/core/internals/construction.py:481, in dict_to_mgr(data, index, columns, dtype, typ, copy)\n    477     else:\n    478         # dtype check to exclude e.g. range objects, scalars\n    479         arrays = [x.copy() if hasattr(x, \"dtype\") else x for x in arrays]\n--> 481 return arrays_to_mgr(arrays, columns, index, dtype=dtype, typ=typ, consolidate=copy)\n\nFile /usr/local/lib/python3.10/dist-packages/pandas/core/internals/construction.py:115, in arrays_to_mgr(arrays, columns, index, dtype, verify_integrity, typ, consolidate)\n    112 if verify_integrity:\n    113     # figure out the index, if necessary\n    114     if index is None:\n--> 115         index = _extract_index(arrays)\n    116     else:\n    117         index = ensure_index(index)\n\nFile /usr/local/lib/python3.10/dist-packages/pandas/core/internals/construction.py:645, in _extract_index(data)\n    642         raise ValueError(\"Per-column arrays must each be 1-dimensional\")\n    644 if not indexes and not raw_lengths:\n--> 645     raise ValueError(\"If using all scalar values, you must pass an index\")\n    647 if have_series:\n    648     index = union_indexes(indexes)\n\nValueError: If using all scalar values, you must pass an index\n```\n\n\nMy Jupyter notebook using the Python 3 (Ubuntu Linux) kernel contains:\n\n```python\nimport matplotlib.pyplot as plt\n\n\n# Choose a document index to visualize (e.g., the first document)\ndocument_index = 0\n\nimport pandas as pd\nimport seaborn as sns\nimport matplotlib.pyplot as plt\n\n# Assuming you have already obtained 'topics' and 'probs' using the 'transform' method\ntopics, probs = topic_model.transform(test_requs)\n\n# Choose a document index to visualize (e.g., the first document)\ndocument_index = 0\n\n# Get the topics and their probabilities for the chosen document\ndocument_topics = topics[document_index]\ndocument_probabilities = probs[document_index]\n\n# Create a DataFrame for visualization\ndf = pd.DataFrame({'Topics': document_topics, 'Probabilities': document_probabilities})\n\n# Create a horizontal bar plot using Seaborn\nplt.figure(figsize=(10, 6))\nsns.barplot(x='Probabilities', y='Topics', data=df, color='skyblue')\nplt.xlabel('Probability')\nplt.ylabel('Topic')\nplt.title(f'Topic Distribution for Document {document_index + 1}')\nplt.show()\n\n```\n\n\n\n</details>","date":"2023-10-10T20:52:01.067Z"}],"sender_id":"d9218c0f-616b-453d-85a3-dcbe9ee8ddba"}
{"date":"2023-10-10T20:52:01.073Z","event":"chat","generating":false,"history":[{"author_id":"chatgpt","content":"The error message indicates that you need to pass an index when creating the DataFrame. To fix the code, you need to add an index parameter to the `pd.DataFrame` function. \n\nHere's the updated code:\n\n```python\nimport matplotlib.pyplot as plt\nimport pandas as pd\nimport seaborn as sns\n\n# Assuming you have already obtained 'topics' and 'probs' using the 'transform' method\ntopics, probs = topic_model.transform(test_requs)\n\n# Choose a document index to visualize (e.g., the first document)\ndocument_index = 0\n\n# Get the topics and their probabilities for the chosen document\ndocument_topics = topics[document_index]\ndocument_probabilities = probs[document_index]\n\n# Create a DataFrame for visualization\ndf = pd.DataFrame({'Topics': document_topics, 'Probabilities': document_probabilities}, index=range(len(document_topics)))\n\n# Create a horizontal bar plot using Seaborn\nplt.figure(figsize=(10, 6))\nsns.barplot(x='Probabilities', y='Topics', data=df, color='skyblue')\nplt.xlabel('Probability')\nplt.ylabel('Topic')\nplt.title(f'Topic Distribution for Document {document_index + 1}')\nplt.show()\n```\nThis code adds the `index` parameter in the `pd.DataFrame` call, providing a range index that matches the length of the `document_topics` array.","date":"2023-10-10T20:52:01.073Z"}],"reply_to":"2023-10-10T20:52:01.067Z","sender_id":"chatgpt"}
{"date":"2023-10-10T21:03:36.855Z","event":"chat","history":[{"author_id":"d9218c0f-616b-453d-85a3-dcbe9ee8ddba","content":"<span class=\"user-mention\" account-id=chatgpt>@ChatGPT</span> help me fix my code.\n\n<details><summary>Context</summary>\n\n\nI ran a cell in a Jupyter notebook.\n\nI received the following error:\n\n```python\n---------------------------------------------------------------------------\nAttributeError                            Traceback (most recent call last)\nFile /usr/local/lib/python3.10/dist-packages/IPython/core/formatters.py:344, in BaseFormatter.__call__(self, obj)\n    342     method = get_real_method(obj, self.print_method)\n    343     if method is not None:\n--> 344         return method()\n    345     return None\n    346 else:\n\nFile /usr/local/lib/python3.10/dist-packages/pandas/io/formats/style.py:383, in Styler._repr_html_(self)\n    378 \"\"\"\n    379 Hooks into Jupyter notebook rich display system, which calls _repr_html_ by\n    380 default if an object is returned at the end of a cell.\n    381 \"\"\"\n    382 if get_option(\"styler.render.repr\") == \"html\":\n--> 383     return self.to_html()\n-> 1308 html = obj._render_html(\n--> 205     d = self._render(sparse_index, sparse_columns, max_rows, max_cols, \"&nbsp;\")\n--> 162     self._compute()\n--> 257     r = func(self)(*args, **kwargs)\n-> 1650     result = func(data, **kwargs)\nFile /usr/local/lib/python3.10/dist-packages/pandas/io/formats/style.py:3629, in _background_gradient(data, cmap, low, high, text_color_threshold, vmin, vmax, gmap, text_only)\n   3625     rgbas = _matplotlib.colormaps[_matplotlib.rcParams[\"image.cmap\"]](\n   3626         norm(gmap)\n   3627     )\n   3628 else:\n-> 3629     rgbas = _matplotlib.colormaps.get_cmap(cmap)(norm(gmap))\n   3631 def relative_luminance(rgba) -> float:\n   3632     \"\"\"\n   3633     Calculate relative luminance of a color.\n   3634 \n   (...)\n   3645         The relative luminance as a value from 0 to 1\n   3646     \"\"\"\n\nAttributeError: 'ColormapRegistry' object has no attribute 'get_cmap'\n```\n\n\nMy Jupyter notebook using the Python 3 (Ubuntu Linux) kernel contains:\n\n```python\n# Calculate the topic distributions on a token-level\ntopic_distr, topic_token_distr = topic_model.approximate_distribution(train_requs, calculate_tokens=True)\n\n# Visualize the token-level distributions\ndf = topic_model.visualize_approximate_distribution(train_requs[1], topic_token_distr[1])\ndf\n\n```\n\n\n\n</details>","date":"2023-10-10T21:03:36.855Z"}],"sender_id":"d9218c0f-616b-453d-85a3-dcbe9ee8ddba"}
{"date":"2023-10-10T21:03:36.861Z","event":"chat","generating":false,"history":[{"author_id":"chatgpt","content":"The error message suggests that the `'ColormapRegistry'` object does not have the attribute `'get_cmap'`. This error is likely occurring in the `topic_model.visualize_approximate_distribution()` function.\n\nTo resolve this issue, you can try the following steps:\n\n1. Update the `topic_model` library to the latest version. This can be done by running `!pip install --upgrade topic_model` in a code cell.\n2. Import the `get_cmap` function directly from the `matplotlib.cm` module. Add the following line at the beginning of your code:\n\n   ```python\n   from matplotlib.cm import get_cmap\n   ```\n\n   This ensures that the `'get_cmap'` function is available in your code.\n3. If the above steps do not resolve the issue, there may be a bug in the `topic_model` library. In that case, you can try reaching out to the library's maintainer for support or look for alternative libraries or approaches to accomplish your task.\n\nAfter applying these changes, your updated code should look like:\n\n```python\nfrom matplotlib.cm import get_cmap\n\n# Calculate the topic distributions on a token-level\ntopic_distr, topic_token_distr = topic_model.approximate_distribution(train_requs, calculate_tokens=True)\n\n# Visualize the token-level distributions\ndf = topic_model.visualize_approximate_distribution(train_requs[1], topic_token_distr[1])\ndf\n```\n\nTry running the code again to see if the error has been resolved.","date":"2023-10-10T21:03:36.861Z"}],"reply_to":"2023-10-10T21:03:36.855Z","sender_id":"chatgpt"}
{"date":"2023-10-10T21:04:29.056Z","event":"chat","history":[{"author_id":"d9218c0f-616b-453d-85a3-dcbe9ee8ddba","content":"<span class=\"user-mention\" account-id=chatgpt>@ChatGPT</span> help me fix my code.\n\n<details><summary>Context</summary>\n\n\nI ran a cell in a Jupyter notebook.\n\nI received the following error:\n\n```python\n---------------------------------------------------------------------------\nAttributeError                            Traceback (most recent call last)\nFile /usr/local/lib/python3.10/dist-packages/IPython/core/formatters.py:344, in BaseFormatter.__call__(self, obj)\n    342     method = get_real_method(obj, self.print_method)\n    343     if method is not None:\n--> 344         return method()\n    345     return None\n    346 else:\n\nFile /usr/local/lib/python3.10/dist-packages/pandas/io/formats/style.py:383, in Styler._repr_html_(self)\n    378 \"\"\"\n    379 Hooks into Jupyter notebook rich display system, which calls _repr_html_ by\n    380 default if an object is returned at the end of a cell.\n    381 \"\"\"\n    382 if get_option(\"styler.render.repr\") == \"html\":\n--> 383     return self.to_html()\n-> 1308 html = obj._render_html(\n--> 205     d = self._render(sparse_index, sparse_columns, max_rows, max_cols, \"&nbsp;\")\n--> 162     self._compute()\n--> 257     r = func(self)(*args, **kwargs)\n-> 1650     result = func(data, **kwargs)\nFile /usr/local/lib/python3.10/dist-packages/pandas/io/formats/style.py:3629, in _background_gradient(data, cmap, low, high, text_color_threshold, vmin, vmax, gmap, text_only)\n   3625     rgbas = _matplotlib.colormaps[_matplotlib.rcParams[\"image.cmap\"]](\n   3626         norm(gmap)\n   3627     )\n   3628 else:\n-> 3629     rgbas = _matplotlib.colormaps.get_cmap(cmap)(norm(gmap))\n   3631 def relative_luminance(rgba) -> float:\n   3632     \"\"\"\n   3633     Calculate relative luminance of a color.\n   3634 \n   (...)\n   3645         The relative luminance as a value from 0 to 1\n   3646     \"\"\"\n\nAttributeError: 'ColormapRegistry' object has no attribute 'get_cmap'\n```\n\n\nMy Jupyter notebook using the Python 3 (Ubuntu Linux) kernel contains:\n\n```python\nfrom matplotlib.cm import get_cmap\n\n# Calculate the topic distributions on a token-level\ntopic_distr, topic_token_distr = topic_model.approximate_distribution(train_requs, calculate_tokens=True)\n\n# Visualize the token-level distributions\ndf = topic_model.visualize_approximate_distribution(train_requs[1], topic_token_distr[1])\ndf\n\n```\n\n\n\n</details>","date":"2023-10-10T21:04:29.056Z"}],"sender_id":"d9218c0f-616b-453d-85a3-dcbe9ee8ddba"}
{"date":"2023-10-10T21:04:29.062Z","event":"chat","generating":false,"history":[{"author_id":"chatgpt","content":"It appears that the error is caused by the `get_cmap` function in the `matplotlib.cm` module. The error message suggests that the `'ColormapRegistry'` object does not have an attribute called `'get_cmap'`.\n\nTo fix this issue, you can try importing `get_cmap` directly from `'matplotlib.pyplot'` instead of `'matplotlib.cm'`:\n\n```python\nfrom matplotlib.pyplot import get_cmap\n```\n\nMake sure to update the import statement in your code accordingly.\n\nIf the issue persists, you may need to check if there are any conflicts between different versions of matplotlib or if there are any missing dependencies.","date":"2023-10-10T21:04:29.062Z"}],"reply_to":"2023-10-10T21:04:29.056Z","sender_id":"chatgpt"}
{"date":"2023-10-10T21:04:51.792Z","event":"chat","history":[{"author_id":"d9218c0f-616b-453d-85a3-dcbe9ee8ddba","content":"<span class=\"user-mention\" account-id=chatgpt>@ChatGPT</span> help me fix my code.\n\n<details><summary>Context</summary>\n\n\nI ran a cell in a Jupyter notebook.\n\nI received the following error:\n\n```python\n---------------------------------------------------------------------------\nAttributeError                            Traceback (most recent call last)\nFile /usr/local/lib/python3.10/dist-packages/IPython/core/formatters.py:344, in BaseFormatter.__call__(self, obj)\n    342     method = get_real_method(obj, self.print_method)\n    343     if method is not None:\n--> 344         return method()\n    345     return None\n    346 else:\n\nFile /usr/local/lib/python3.10/dist-packages/pandas/io/formats/style.py:383, in Styler._repr_html_(self)\n    378 \"\"\"\n    379 Hooks into Jupyter notebook rich display system, which calls _repr_html_ by\n    380 default if an object is returned at the end of a cell.\n    381 \"\"\"\n    382 if get_option(\"styler.render.repr\") == \"html\":\n--> 383     return self.to_html()\n-> 1308 html = obj._render_html(\n--> 205     d = self._render(sparse_index, sparse_columns, max_rows, max_cols, \"&nbsp;\")\n--> 162     self._compute()\n--> 257     r = func(self)(*args, **kwargs)\n-> 1650     result = func(data, **kwargs)\nFile /usr/local/lib/python3.10/dist-packages/pandas/io/formats/style.py:3629, in _background_gradient(data, cmap, low, high, text_color_threshold, vmin, vmax, gmap, text_only)\n   3625     rgbas = _matplotlib.colormaps[_matplotlib.rcParams[\"image.cmap\"]](\n   3626         norm(gmap)\n   3627     )\n   3628 else:\n-> 3629     rgbas = _matplotlib.colormaps.get_cmap(cmap)(norm(gmap))\n   3631 def relative_luminance(rgba) -> float:\n   3632     \"\"\"\n   3633     Calculate relative luminance of a color.\n   3634 \n   (...)\n   3645         The relative luminance as a value from 0 to 1\n   3646     \"\"\"\n\nAttributeError: 'ColormapRegistry' object has no attribute 'get_cmap'\n```\n\n\nMy Jupyter notebook using the Python 3 (Ubuntu Linux) kernel contains:\n\n```python\nfrom matplotlib.pyplot import get_cmap\n\n# Calculate the topic distributions on a token-level\ntopic_distr, topic_token_distr = topic_model.approximate_distribution(train_requs, calculate_tokens=True)\n\n# Visualize the token-level distributions\ndf = topic_model.visualize_approximate_distribution(train_requs[1], topic_token_distr[1])\ndf\n\n```\n\n\n\n</details>","date":"2023-10-10T21:04:51.792Z"}],"sender_id":"d9218c0f-616b-453d-85a3-dcbe9ee8ddba"}
{"date":"2023-10-10T21:04:51.798Z","event":"chat","generating":false,"history":[{"author_id":"chatgpt","content":"The error message indicates that the 'ColormapRegistry' object does not have the 'get_cmap' attribute. This error is most likely caused by a version mismatch between the 'matplotlib' library and the 'pandas' library.\n\nTo fix this issue, you can try updating both libraries to their latest versions. This can be done by running the following code in a cell before executing your current code:\n\n```python\n!pip install --upgrade matplotlib pandas\n```\n\nAlternatively, you can try downgrading the 'matplotlib' library to a version that is compatible with your current 'pandas' library. To do this, you can run the following code:\n\n```python\n!pip install matplotlib==<version>\n```\n\nReplace `<version>` with a version number that is compatible with your current 'pandas' library. You can check the compatibility of different 'matplotlib' versions with your 'pandas' library in the 'matplotlib' documentation.\n\nAfter updating or downgrading the required libraries, re-run the cell containing your code and check if the error is resolved.","date":"2023-10-10T21:04:51.798Z"}],"reply_to":"2023-10-10T21:04:51.792Z","sender_id":"chatgpt"}
{"date":"2023-10-10T21:05:41.871Z","event":"chat","history":[{"author_id":"d9218c0f-616b-453d-85a3-dcbe9ee8ddba","content":"<span class=\"user-mention\" account-id=chatgpt>@ChatGPT</span> help me fix my code.\n\n<details><summary>Context</summary>\n\n\nI ran a cell in a Jupyter notebook.\n\nI received the following error:\n\n```python\n---------------------------------------------------------------------------\nAttributeError                            Traceback (most recent call last)\nFile /usr/local/lib/python3.10/dist-packages/IPython/core/formatters.py:344, in BaseFormatter.__call__(self, obj)\n    342     method = get_real_method(obj, self.print_method)\n    343     if method is not None:\n--> 344         return method()\n    345     return None\n    346 else:\n\nFile /usr/local/lib/python3.10/dist-packages/pandas/io/formats/style.py:383, in Styler._repr_html_(self)\n    378 \"\"\"\n    379 Hooks into Jupyter notebook rich display system, which calls _repr_html_ by\n    380 default if an object is returned at the end of a cell.\n    381 \"\"\"\n    382 if get_option(\"styler.render.repr\") == \"html\":\n--> 383     return self.to_html()\n-> 1308 html = obj._render_html(\n--> 205     d = self._render(sparse_index, sparse_columns, max_rows, max_cols, \"&nbsp;\")\n--> 162     self._compute()\n--> 257     r = func(self)(*args, **kwargs)\n-> 1650     result = func(data, **kwargs)\nFile /usr/local/lib/python3.10/dist-packages/pandas/io/formats/style.py:3629, in _background_gradient(data, cmap, low, high, text_color_threshold, vmin, vmax, gmap, text_only)\n   3625     rgbas = _matplotlib.colormaps[_matplotlib.rcParams[\"image.cmap\"]](\n   3626         norm(gmap)\n   3627     )\n   3628 else:\n-> 3629     rgbas = _matplotlib.colormaps.get_cmap(cmap)(norm(gmap))\n   3631 def relative_luminance(rgba) -> float:\n   3632     \"\"\"\n   3633     Calculate relative luminance of a color.\n   3634 \n   (...)\n   3645         The relative luminance as a value from 0 to 1\n   3646     \"\"\"\n\nAttributeError: 'ColormapRegistry' object has no attribute 'get_cmap'\n```\n\n\nMy Jupyter notebook using the Python 3 (Ubuntu Linux) kernel contains:\n\n```python\nfrom matplotlib.pyplot import get_cmap\n\n# Calculate the topic distributions on a token-level\ntopic_distr, topic_token_distr = topic_model.approximate_distribution(train_requs, calculate_tokens=True)\n\n# Visualize the token-level distributions\ndf = topic_model.visualize_approximate_distribution(train_requs[1], topic_token_distr[1])\ndf\n\n```\n\n\n\n</details>","date":"2023-10-10T21:05:41.871Z"}],"sender_id":"d9218c0f-616b-453d-85a3-dcbe9ee8ddba"}
{"date":"2023-10-10T21:05:41.877Z","event":"chat","generating":false,"history":[{"author_id":"chatgpt","content":"The error message indicates that there is an `AttributeError` related to the `get_cmap` function in the `matplotlib.pyplot` module.\n\nTo fix the code, you can try the following steps:\n\n1. Import the `matplotlib.cm` module instead of `matplotlib.pyplot`.\n2. Replace `get_cmap` with `cm.get_cmap`.\n\nHere's the updated code:\n\n```python\nfrom matplotlib import cm\n\n# Calculate the topic distributions on a token-level\ntopic_distr, topic_token_distr = topic_model.approximate_distribution(train_requs, calculate_tokens=True)\n\n# Visualize the token-level distributions\ndf = topic_model.visualize_approximate_distribution(train_requs[1], topic_token_distr[1], cmap=cm.get_cmap('viridis'))\ndf\n```\n\nThese changes should resolve the AttributeError and allow the code to run without errors.","date":"2023-10-10T21:05:41.877Z"}],"reply_to":"2023-10-10T21:05:41.871Z","sender_id":"chatgpt"}
{"date":"2023-10-10T21:06:08.582Z","event":"chat","history":[{"author_id":"d9218c0f-616b-453d-85a3-dcbe9ee8ddba","content":"<span class=\"user-mention\" account-id=chatgpt>@ChatGPT</span> help me fix my code.\n\n<details><summary>Context</summary>\n\n\nI ran a cell in a Jupyter notebook.\n\nI received the following error:\n\n```python\n---------------------------------------------------------------------------\nTypeError                                 Traceback (most recent call last)\nCell In[27], line 7\n      4 topic_distr, topic_token_distr = topic_model.approximate_distribution(train_requs, calculate_tokens=True)\n      6 # Visualize the token-level distributions\n----> 7 df = topic_model.visualize_approximate_distribution(train_requs[1], topic_token_distr[1], cmap=cm.get_cmap('viridis'))\n      8 df\n     10 # Calculate the topic distributions on a token-level\n\nTypeError: BERTopic.visualize_approximate_distribution() got an unexpected keyword argument 'cmap'\n```\n\n\nMy Jupyter notebook using the Python 3 (Ubuntu Linux) kernel contains:\n\n```python\nfrom matplotlib import cm\n\n# Calculate the topic distributions on a token-level\ntopic_distr, topic_token_distr = topic_model.approximate_distribution(train_requs, calculate_tokens=True)\n\n# Visualize the token-level distributions\ndf = topic_model.visualize_approximate_distribution(train_requs[1], topic_token_distr[1], cmap=cm.get_cmap('viridis'))\ndf\n\n# Calculate the topic distributions on a token-level\ntopic_distr, topic_token_distr = topic_model.approximate_distribution(train_requs, calculate_tokens=True)\n\n# Visualize the token-level distributions\ndf = topic_model.visualize_approximate_distribution(train_requs[1], topic_token_distr[1])\ndf\n\n```\n\n\n\n</details>","date":"2023-10-10T21:06:08.582Z"}],"sender_id":"d9218c0f-616b-453d-85a3-dcbe9ee8ddba"}
{"date":"2023-10-10T21:06:08.588Z","event":"chat","generating":false,"history":[{"author_id":"chatgpt","content":"The error message you received indicates that the `visualize_approximate_distribution()` method does not expect the `cmap` keyword argument. To fix this error, you need to remove the `cmap=cm.get_cmap('viridis')` part from the `visualize_approximate_distribution()` method call.\n\nHere's the updated code:\n\n```python\nfrom matplotlib import cm\n\n# Calculate the topic distributions on a token-level\ntopic_distr, topic_token_distr = topic_model.approximate_distribution(train_requs, calculate_tokens=True)\n\n# Visualize the token-level distributions\ndf = topic_model.visualize_approximate_distribution(train_requs[1], topic_token_distr[1])\ndf\n```\n\nAfter making this change, the error should be resolved.","date":"2023-10-10T21:06:08.588Z"}],"reply_to":"2023-10-10T21:06:08.582Z","sender_id":"chatgpt"}
{"date":"2023-10-10T21:06:27.281Z","event":"chat","history":[{"author_id":"d9218c0f-616b-453d-85a3-dcbe9ee8ddba","content":"<span class=\"user-mention\" account-id=chatgpt>@ChatGPT</span> help me fix my code.\n\n<details><summary>Context</summary>\n\n\nI ran a cell in a Jupyter notebook.\n\nI received the following error:\n\n```python\n---------------------------------------------------------------------------\nAttributeError                            Traceback (most recent call last)\nFile /usr/local/lib/python3.10/dist-packages/IPython/core/formatters.py:344, in BaseFormatter.__call__(self, obj)\n    342     method = get_real_method(obj, self.print_method)\n    343     if method is not None:\n--> 344         return method()\n    345     return None\n    346 else:\n\nFile /usr/local/lib/python3.10/dist-packages/pandas/io/formats/style.py:383, in Styler._repr_html_(self)\n    378 \"\"\"\n    379 Hooks into Jupyter notebook rich display system, which calls _repr_html_ by\n    380 default if an object is returned at the end of a cell.\n    381 \"\"\"\n    382 if get_option(\"styler.render.repr\") == \"html\":\n--> 383     return self.to_html()\n-> 1308 html = obj._render_html(\n--> 205     d = self._render(sparse_index, sparse_columns, max_rows, max_cols, \"&nbsp;\")\n--> 162     self._compute()\n--> 257     r = func(self)(*args, **kwargs)\n-> 1650     result = func(data, **kwargs)\nFile /usr/local/lib/python3.10/dist-packages/pandas/io/formats/style.py:3629, in _background_gradient(data, cmap, low, high, text_color_threshold, vmin, vmax, gmap, text_only)\n   3625     rgbas = _matplotlib.colormaps[_matplotlib.rcParams[\"image.cmap\"]](\n   3626         norm(gmap)\n   3627     )\n   3628 else:\n-> 3629     rgbas = _matplotlib.colormaps.get_cmap(cmap)(norm(gmap))\n   3631 def relative_luminance(rgba) -> float:\n   3632     \"\"\"\n   3633     Calculate relative luminance of a color.\n   3634 \n   (...)\n   3645         The relative luminance as a value from 0 to 1\n   3646     \"\"\"\n\nAttributeError: 'ColormapRegistry' object has no attribute 'get_cmap'\n```\n\n\nMy Jupyter notebook using the Python 3 (Ubuntu Linux) kernel contains:\n\n```python\nfrom matplotlib import cm\n\n# Calculate the topic distributions on a token-level\ntopic_distr, topic_token_distr = topic_model.approximate_distribution(train_requs, calculate_tokens=True)\n\n# Visualize the token-level distributions\ndf = topic_model.visualize_approximate_distribution(train_requs[1], topic_token_distr[1])\ndf\n```\n\n\n\n</details>","date":"2023-10-10T21:06:27.281Z"}],"sender_id":"d9218c0f-616b-453d-85a3-dcbe9ee8ddba"}
{"date":"2023-10-10T21:06:27.287Z","event":"chat","generating":false,"history":[{"author_id":"chatgpt","content":"The error message suggests that there is an issue with the `get_cmap()` method in the `ColormapRegistry` object. \n\nTo fix the error, you can try the following steps:\n\n1. Check the version of `matplotlib` being used. This error could occur if you are using an older version that does not have the `get_cmap()` method in the `ColormapRegistry` object. \n\n   You can check the version of `matplotlib` by running the following command in a code cell in your Jupyter notebook:\n\n   ```python\n   import matplotlib\n   print(matplotlib.__version__)\n   ```\n\n   If the version is outdated, you can upgrade `matplotlib` by running the following command in a code cell:\n\n   ```python\n   !pip install --upgrade matplotlib\n   ```\n\n2. Alternatively, you can try importing `matplotlib.pyplot` instead of just `matplotlib` to see if it resolves the issue. Modify your code to replace:\n\n   ```python\n   from matplotlib import cm\n   ```\n\n   with:\n\n   ```python\n   import matplotlib.pyplot as plt\n   ```\n\n   Make sure to update any subsequent references to `cm` in your code to `plt.cm`.\n\n   For example, replace `cm.get_cmap()` with `plt.cm.get_cmap()`.\n\n   This change is necessary because the `ColormapRegistry` object is part of `matplotlib.pyplot` module.\n\nAfter making these changes, run your code again and see if the error is resolved.","date":"2023-10-10T21:06:27.287Z"}],"reply_to":"2023-10-10T21:06:27.281Z","sender_id":"chatgpt"}
{"date":"2023-10-10T21:19:42.767Z","event":"chat","history":[{"author_id":"d9218c0f-616b-453d-85a3-dcbe9ee8ddba","content":"<span class=\"user-mention\" account-id=chatgpt>@ChatGPT</span> help me fix my code.\n\n<details><summary>Context</summary>\n\n\nI ran a cell in a Jupyter notebook.\n\nI received the following error:\n\n```python\n---------------------------------------------------------------------------\nImportError                               Traceback (most recent call last)\nFile ~/.local/lib/python3.10/site-packages/pandas/__init__.py:23\n     21 try:\n     22     # numpy compat\n---> 23     from pandas.compat import (\n     24         is_numpy_dev as _is_numpy_dev,  # pyright: ignore[reportUnusedImport] # noqa: F401,E501\n     25     )\n     26 except ImportError as _err:  # pragma: no cover\n\nFile ~/.local/lib/python3.10/site-packages/pandas/compat/__init__.py:26\n     25 import pandas.compat.compressors\n---> 26 from pandas.compat.numpy import is_numpy_dev\n     27 from pandas.compat.pyarrow import (\n     28     pa_version_under7p0,\n     29     pa_version_under8p0,\n     27     _module = _err.name\n---> 28     raise ImportError(\n     29         f\"C extension: {_module} not built. If you want to import \"\n     30         \"pandas from the source directory, you may need to run \"\n     31         \"'python setup.py build_ext' to build the C extensions first.\"\n     32     ) from _err\n     34 from pandas._config import (\n     35     get_option,\n     36     set_option,\n   (...)\n     40     options,\n     41 )\n     43 # let init-time option registration happen\n\nImportError: C extension: None not built. If you want to import pandas from the source directory, you may need to run 'python setup.py build_ext' to build the C extensions first.\n```\n\n\nMy Jupyter notebook using the Python 3 (Ubuntu Linux) kernel contains:\n\n```python\nfrom bertopic.representation import KeyBERTInspired\nfrom bertopic.representation import PartOfSpeech\nfrom bertopic.representation import MaximalMarginalRelevance\nfrom sklearn.datasets import fetch_20newsgroups\nfrom bertopic import BERTopic\nimport pandas as pd\nfrom sklearn.model_selection import train_test_split\n```\n\n\n\n</details>","date":"2023-10-10T21:19:42.767Z"}],"sender_id":"d9218c0f-616b-453d-85a3-dcbe9ee8ddba"}
{"date":"2023-10-10T21:19:42.773Z","event":"chat","generating":false,"history":[{"author_id":"chatgpt","content":"The error message indicates that there is an `ImportError` when trying to import certain modules in `pandas`. Specifically, it says that the C extension is not built.\n\nTo fix this issue, you can try reinstalling `pandas` in the current environment. You can do this by running the following command in a code cell:\n\n```\n!pip install --upgrade pandas\n```\n\nAfter reinstalling `pandas`, try running the cell again and see if the error persists. If it still persists, you may need to check if there are any compatibility issues between the pandas version you are using and the version of Python running in your environment.\n\nIt is worth noting that the error message also suggests running `'python setup.py build_ext'` to build the C extensions first. However, in most cases, simply reinstalling `pandas` should resolve the issue.","date":"2023-10-10T21:19:42.773Z"}],"reply_to":"2023-10-10T21:19:42.767Z","sender_id":"chatgpt"}
{"date":"2023-10-10T21:20:06.796Z","event":"chat","history":[{"author_id":"d9218c0f-616b-453d-85a3-dcbe9ee8ddba","content":"<span class=\"user-mention\" account-id=chatgpt>@ChatGPT</span> help me fix my code.\n\n<details><summary>Context</summary>\n\n\nI ran a cell in a Jupyter notebook.\n\nI received the following error:\n\n```python\n---------------------------------------------------------------------------\nImportError                               Traceback (most recent call last)\nFile ~/.local/lib/python3.10/site-packages/pandas/__init__.py:23\n     21 try:\n     22     # numpy compat\n---> 23     from pandas.compat import (\n     24         is_numpy_dev as _is_numpy_dev,  # pyright: ignore[reportUnusedImport] # noqa: F401,E501\n     25     )\n     26 except ImportError as _err:  # pragma: no cover\n\nFile ~/.local/lib/python3.10/site-packages/pandas/compat/__init__.py:26\n     25 import pandas.compat.compressors\n---> 26 from pandas.compat.numpy import is_numpy_dev\n     27 from pandas.compat.pyarrow import (\n     28     pa_version_under7p0,\n     29     pa_version_under8p0,\n     27     _module = _err.name\n---> 28     raise ImportError(\n     29         f\"C extension: {_module} not built. If you want to import \"\n     30         \"pandas from the source directory, you may need to run \"\n     31         \"'python setup.py build_ext' to build the C extensions first.\"\n     32     ) from _err\n     34 from pandas._config import (\n     35     get_option,\n     36     set_option,\n   (...)\n     40     options,\n     41 )\n     43 # let init-time option registration happen\n\nImportError: C extension: None not built. If you want to import pandas from the source directory, you may need to run 'python setup.py build_ext' to build the C extensions first.\n```\n\n\nMy Jupyter notebook using the Python 3 (Ubuntu Linux) kernel contains:\n\n```python\nfrom bertopic.representation import KeyBERTInspired\nfrom bertopic.representation import PartOfSpeech\nfrom bertopic.representation import MaximalMarginalRelevance\nfrom sklearn.datasets import fetch_20newsgroups\nfrom bertopic import BERTopic\n!pip install --upgrade pandas\nimport pandas as pd\nfrom sklearn.model_selection import train_test_split\n```\n\n\n\n</details>","date":"2023-10-10T21:20:06.796Z"}],"sender_id":"d9218c0f-616b-453d-85a3-dcbe9ee8ddba"}
{"date":"2023-10-10T21:20:06.802Z","event":"chat","generating":false,"history":[{"author_id":"chatgpt","content":"The error message suggests that there is an issue with importing the `pandas` library in your Jupyter notebook. One possible solution is to try reinstalling `pandas` using the `!pip install` command. Here's an updated version of your code:\n\n```python\n!pip install --upgrade pandas\n\nfrom bertopic.representation import KeyBERTInspired\nfrom bertopic.representation import PartOfSpeech\nfrom bertopic.representation import MaximalMarginalRelevance\nfrom sklearn.datasets import fetch_20newsgroups\nimport pandas as pd  # Import pandas after reinstalling it\nfrom sklearn.model_selection import train_test_split\n```\n\nBy running `!pip install --upgrade pandas` before importing `pandas`, you can ensure that a fresh version of the library is installed, potentially resolving any conflicts or build issues.","date":"2023-10-10T21:20:06.802Z"}],"reply_to":"2023-10-10T21:20:06.796Z","sender_id":"chatgpt"}
{"date":"2023-10-10T21:20:31.346Z","event":"chat","history":[{"author_id":"d9218c0f-616b-453d-85a3-dcbe9ee8ddba","content":"<span class=\"user-mention\" account-id=chatgpt>@ChatGPT</span> help me fix my code.\n\n<details><summary>Context</summary>\n\n\nI ran a cell in a Jupyter notebook.\n\nI received the following error:\n\n```python\n---------------------------------------------------------------------------\nImportError                               Traceback (most recent call last)\nFile ~/.local/lib/python3.10/site-packages/pandas/__init__.py:23\n     21 try:\n     22     # numpy compat\n---> 23     from pandas.compat import (\n     24         is_numpy_dev as _is_numpy_dev,  # pyright: ignore[reportUnusedImport] # noqa: F401,E501\n     25     )\n     26 except ImportError as _err:  # pragma: no cover\n\nFile ~/.local/lib/python3.10/site-packages/pandas/compat/__init__.py:26\n     25 import pandas.compat.compressors\n---> 26 from pandas.compat.numpy import is_numpy_dev\n     27 from pandas.compat.pyarrow import (\n     28     pa_version_under7p0,\n     29     pa_version_under8p0,\n     27     _module = _err.name\n---> 28     raise ImportError(\n     29         f\"C extension: {_module} not built. If you want to import \"\n     30         \"pandas from the source directory, you may need to run \"\n     31         \"'python setup.py build_ext' to build the C extensions first.\"\n     32     ) from _err\n     34 from pandas._config import (\n     35     get_option,\n     36     set_option,\n   (...)\n     40     options,\n     41 )\n     43 # let init-time option registration happen\n\nImportError: C extension: None not built. If you want to import pandas from the source directory, you may need to run 'python setup.py build_ext' to build the C extensions first.\n```\n\n\nMy Jupyter notebook using the Python 3 (Ubuntu Linux) kernel contains:\n\n```python\n!pip install --upgrade pandas\n\nfrom bertopic.representation import KeyBERTInspired\nfrom bertopic.representation import PartOfSpeech\nfrom bertopic.representation import MaximalMarginalRelevance\nfrom sklearn.datasets import fetch_20newsgroups\nimport pandas as pd  # Import pandas after reinstalling it\nfrom sklearn.model_selection import train_test_split\n```\n\n\n\n</details>","date":"2023-10-10T21:20:31.346Z"}],"sender_id":"d9218c0f-616b-453d-85a3-dcbe9ee8ddba"}
{"date":"2023-10-10T21:20:31.352Z","event":"chat","generating":false,"history":[{"author_id":"chatgpt","content":"The error message suggests that the pandas library is not installed properly or there is a problem with the C extensions. To fix this, you can try the following steps:\n\n1. Make sure you have the latest version of pandas installed by running the command `!pip install --upgrade pandas`.\n\n2. If the first step doesn't resolve the issue, try reinstalling pandas by running `!pip uninstall pandas` and then `!pip install pandas`.\n\n3. If the issue persists, try reinstalling pandas with additional flags by running `!pip install --no-cache-dir --force-reinstall pandas`.\n\n4. If none of the above steps work, you can try installing pandas from the source directory by running `!python setup.py build_ext` before importing it in your notebook.\n\nMake sure to restart the kernel after performing the above steps and then rerun the cell.","date":"2023-10-10T21:20:31.352Z"}],"reply_to":"2023-10-10T21:20:31.346Z","sender_id":"chatgpt"}
{"date":"2023-10-10T21:23:47.166Z","event":"chat","history":[{"author_id":"d9218c0f-616b-453d-85a3-dcbe9ee8ddba","content":"<span class=\"user-mention\" account-id=chatgpt>@ChatGPT</span> help me fix my code.\n\n<details><summary>Context</summary>\n\n\nI ran a cell in a Jupyter notebook.\n\nI received the following error:\n\n```python\n---------------------------------------------------------------------------\nSystemError                               Traceback (most recent call last)\nCell In[2], line 1\n----> 1 from bertopic.representation import KeyBERTInspired\n      2 from bertopic.representation import PartOfSpeech\n      3 from bertopic.representation import MaximalMarginalRelevance\n\nFile ~/.local/lib/python3.10/site-packages/bertopic/__init__.py:1\n----> 1 from bertopic._bertopic import BERTopic\n      3 __version__ = \"0.15.0\"\n      5 __all__ = [\n      6     \"BERTopic\",\n      7 ]\n\nFile ~/.local/lib/python3.10/site-packages/bertopic/_bertopic.py:38\n     36 # Models\n     37 import hdbscan\n---> 38 from umap import UMAP\n     39 from sklearn.preprocessing import normalize\n     40 from sklearn import __version__ as sklearn_version\n\nFile ~/.local/lib/python3.10/site-packages/umap/__init__.py:2\n      1 from warnings import warn, catch_warnings, simplefilter\n----> 2 from .umap_ import UMAP\n      4 try:\n      5     with catch_warnings():\n\nFile ~/.local/lib/python3.10/site-packages/umap/umap_.py:29\n     27 from scipy.sparse import tril as sparse_tril, triu as sparse_triu\n     28 import scipy.sparse.csgraph\n---> 29 import numba\n     31 import umap.distances as dist\n     33 import umap.sparse as sparse\n\nFile /usr/lib/python3/dist-packages/numba/__init__.py:42\n     38 from numba.core.decorators import (cfunc, generated_jit, jit, njit, stencil,\n     39                                    jit_module)\n     41 # Re-export vectorize decorators and the thread layer querying function\n---> 42 from numba.np.ufunc import (vectorize, guvectorize, threading_layer,\n     43                             get_num_threads, set_num_threads)\n     45 # Re-export Numpy helpers\n     46 from numba.np.numpy_support import carray, farray, from_dtype\n\nFile /usr/lib/python3/dist-packages/numba/np/ufunc/__init__.py:3\n      1 # -*- coding: utf-8 -*-\n----> 3 from numba.np.ufunc.decorators import Vectorize, GUVectorize, vectorize, guvectorize\n      4 from numba.np.ufunc._internal import PyUFunc_None, PyUFunc_Zero, PyUFunc_One\n      5 from numba.np.ufunc import _internal, array_exprs\n\nFile /usr/lib/python3/dist-packages/numba/np/ufunc/decorators.py:3\n      1 import inspect\n----> 3 from numba.np.ufunc import _internal\n      4 from numba.np.ufunc.parallel import ParallelUFuncBuilder, ParallelGUFuncBuilder\n      6 from numba.core.registry import DelayedRegistry\n\nSystemError: initialization of _internal failed without raising an exception\n```\n\n\nMy Jupyter notebook using the Python 3 (Ubuntu Linux) kernel contains:\n\n```python\n\n\nfrom bertopic.representation import KeyBERTInspired\nfrom bertopic.representation import PartOfSpeech\nfrom bertopic.representation import MaximalMarginalRelevance\nfrom sklearn.datasets import fetch_20newsgroups\nimport pandas as pd  # Import pandas after reinstalling it\nfrom sklearn.model_selection import train_test_split\n```\n\n\n\n</details>","date":"2023-10-10T21:23:47.166Z"}],"sender_id":"d9218c0f-616b-453d-85a3-dcbe9ee8ddba"}
{"date":"2023-10-10T21:23:47.172Z","event":"chat","generating":false,"history":[{"author_id":"chatgpt","content":"The error message suggests that there is an issue with the `numba` package. Here are a few possible solutions:\n\n1. Restart the kernel: Sometimes, restarting the Jupyter kernel can resolve import-related issues. You can do this by selecting \"Kernel\" from the top menu and then choosing \"Restart & Clear Output.\"\n\n2. Reinstall `numba`: It's possible that the `numba` package has become corrupted. You can try reinstalling it using the command `!pip install --upgrade numba` in a code cell.\n\n3. Update `numba` and its dependencies: Make sure that you have the latest version of `numba` and its dependencies installed. You can update `numba` using the command `!pip install --upgrade numba` and update all dependencies using `!pip install --upgrade --upgrade-strategy eager numba`.\n\n4. Check for conflicting packages: It's possible that there's a conflict between `numba` and another package that you have installed. You can try removing any conflicting packages and reinstalling `numba` to see if that resolves the issue.\n\nTry these solutions one by one and see if any of them fix the problem.","date":"2023-10-10T21:23:47.172Z"}],"reply_to":"2023-10-10T21:23:47.166Z","sender_id":"chatgpt"}
{"date":"2023-10-10T21:24:46.403Z","event":"chat","history":[{"author_id":"d9218c0f-616b-453d-85a3-dcbe9ee8ddba","content":"<span class=\"user-mention\" account-id=chatgpt>@ChatGPT</span> help me fix my code.\n\n<details><summary>Context</summary>\n\n\nI ran a cell in a Jupyter notebook.\n\nI received the following error:\n\n```python\n---------------------------------------------------------------------------\nSystemError                               Traceback (most recent call last)\nCell In[1], line 1\n----> 1 from bertopic.representation import KeyBERTInspired\n      2 from bertopic.representation import PartOfSpeech\n      3 from bertopic.representation import MaximalMarginalRelevance\n\nFile ~/.local/lib/python3.10/site-packages/bertopic/__init__.py:1\n----> 1 from bertopic._bertopic import BERTopic\n      3 __version__ = \"0.15.0\"\n      5 __all__ = [\n      6     \"BERTopic\",\n      7 ]\n\nFile ~/.local/lib/python3.10/site-packages/bertopic/_bertopic.py:38\n     36 # Models\n     37 import hdbscan\n---> 38 from umap import UMAP\n     39 from sklearn.preprocessing import normalize\n     40 from sklearn import __version__ as sklearn_version\n\nFile ~/.local/lib/python3.10/site-packages/umap/__init__.py:2\n      1 from warnings import warn, catch_warnings, simplefilter\n----> 2 from .umap_ import UMAP\n      4 try:\n      5     with catch_warnings():\n\nFile ~/.local/lib/python3.10/site-packages/umap/umap_.py:29\n     27 from scipy.sparse import tril as sparse_tril, triu as sparse_triu\n     28 import scipy.sparse.csgraph\n---> 29 import numba\n     31 import umap.distances as dist\n     33 import umap.sparse as sparse\n\nFile /usr/lib/python3/dist-packages/numba/__init__.py:42\n     38 from numba.core.decorators import (cfunc, generated_jit, jit, njit, stencil,\n     39                                    jit_module)\n     41 # Re-export vectorize decorators and the thread layer querying function\n---> 42 from numba.np.ufunc import (vectorize, guvectorize, threading_layer,\n     43                             get_num_threads, set_num_threads)\n     45 # Re-export Numpy helpers\n     46 from numba.np.numpy_support import carray, farray, from_dtype\n\nFile /usr/lib/python3/dist-packages/numba/np/ufunc/__init__.py:3\n      1 # -*- coding: utf-8 -*-\n----> 3 from numba.np.ufunc.decorators import Vectorize, GUVectorize, vectorize, guvectorize\n      4 from numba.np.ufunc._internal import PyUFunc_None, PyUFunc_Zero, PyUFunc_One\n      5 from numba.np.ufunc import _internal, array_exprs\n\nFile /usr/lib/python3/dist-packages/numba/np/ufunc/decorators.py:3\n      1 import inspect\n----> 3 from numba.np.ufunc import _internal\n      4 from numba.np.ufunc.parallel import ParallelUFuncBuilder, ParallelGUFuncBuilder\n      6 from numba.core.registry import DelayedRegistry\n\nSystemError: initialization of _internal failed without raising an exception\n```\n\n\nMy Jupyter notebook using the Python 3 (Ubuntu Linux) kernel contains:\n\n```python\n\n\nfrom bertopic.representation import KeyBERTInspired\nfrom bertopic.representation import PartOfSpeech\nfrom bertopic.representation import MaximalMarginalRelevance\nfrom sklearn.datasets import fetch_20newsgroups\nimport pandas as pd  # Import pandas after reinstalling it\nfrom sklearn.model_selection import train_test_split\n```\n\n\n\n</details>","date":"2023-10-10T21:24:46.403Z"}],"sender_id":"d9218c0f-616b-453d-85a3-dcbe9ee8ddba"}
{"date":"2023-10-10T21:24:46.409Z","event":"chat","generating":false,"history":[{"author_id":"chatgpt","content":"It looks like you are experiencing a `SystemError` when running your code. The error message indicates that there is an issue with the initialization of the `_internal` module in the `numba.np.ufunc` package.\n\nTo fix this issue, you can try reinstalling the `numba` package. You can do this by running the following command in a code cell:\n\n```python\n!pip install --upgrade numba\n```\n\nAfter reinstalling `numba`, you can try running your code again to see if the error is resolved. If the issue persists, you may need to check for any additional package dependencies or consult the documentation for the `bertopic` package for further troubleshooting steps.","date":"2023-10-10T21:24:46.409Z"}],"reply_to":"2023-10-10T21:24:46.403Z","sender_id":"chatgpt"}
{"date":"2023-10-10T21:25:16.057Z","event":"chat","history":[{"author_id":"d9218c0f-616b-453d-85a3-dcbe9ee8ddba","content":"<span class=\"user-mention\" account-id=chatgpt>@ChatGPT</span> help me fix my code.\n\n<details><summary>Context</summary>\n\n\nI ran a cell in a Jupyter notebook.\n\nI received the following error:\n\n```python\n---------------------------------------------------------------------------\nImportError                               Traceback (most recent call last)\nCell In[3], line 1\n----> 1 from bertopic.representation import KeyBERTInspired\n      2 from bertopic.representation import PartOfSpeech\n      3 from bertopic.representation import MaximalMarginalRelevance\n\nFile ~/.local/lib/python3.10/site-packages/bertopic/__init__.py:1\n----> 1 from bertopic._bertopic import BERTopic\n      3 __version__ = \"0.15.0\"\n      5 __all__ = [\n      6     \"BERTopic\",\n      7 ]\n\nFile ~/.local/lib/python3.10/site-packages/bertopic/_bertopic.py:38\n     36 # Models\n     37 import hdbscan\n---> 38 from umap import UMAP\n     39 from sklearn.preprocessing import normalize\n     40 from sklearn import __version__ as sklearn_version\n\nFile ~/.local/lib/python3.10/site-packages/umap/__init__.py:2\n      1 from warnings import warn, catch_warnings, simplefilter\n----> 2 from .umap_ import UMAP\n      4 try:\n      5     with catch_warnings():\n\nFile ~/.local/lib/python3.10/site-packages/umap/umap_.py:29\n     27 from scipy.sparse import tril as sparse_tril, triu as sparse_triu\n     28 import scipy.sparse.csgraph\n---> 29 import numba\n     31 import umap.distances as dist\n     33 import umap.sparse as sparse\n\nFile ~/.local/lib/python3.10/site-packages/numba/__init__.py:55\n     50             msg = (\"Numba requires SciPy version 1.0 or greater. Got SciPy \"\n     51                    f\"{scipy.__version__}.\")\n     52             raise ImportError(msg)\n---> 55 _ensure_critical_deps()\n     56 # END DO NOT MOVE\n     57 # ---------------------- WARNING WARNING WARNING ----------------------------\n     60 from ._version import get_versions\n\nFile ~/.local/lib/python3.10/site-packages/numba/__init__.py:42, in _ensure_critical_deps()\n     40     raise ImportError(msg)\n     41 elif numpy_version > (1, 25):\n---> 42     raise ImportError(\"Numba needs NumPy 1.25 or less\")\n     43 try:\n     44     import scipy\n\nImportError: Numba needs NumPy 1.25 or less\n```\n\n\nMy Jupyter notebook using the Python 3 (Ubuntu Linux) kernel contains:\n\n```python\n\n\nfrom bertopic.representation import KeyBERTInspired\nfrom bertopic.representation import PartOfSpeech\nfrom bertopic.representation import MaximalMarginalRelevance\nfrom sklearn.datasets import fetch_20newsgroups\nimport pandas as pd  # Import pandas after reinstalling it\nfrom sklearn.model_selection import train_test_split\n```\n\n\n\n</details>","date":"2023-10-10T21:25:16.057Z"}],"sender_id":"d9218c0f-616b-453d-85a3-dcbe9ee8ddba"}
{"date":"2023-10-10T21:25:16.063Z","event":"chat","generating":false,"history":[{"author_id":"chatgpt","content":"The error message indicates that the `numba` package requires NumPy version 1.25 or less, while the installed version of NumPy is newer.\n\nTo fix this issue, you can try downgrading NumPy to version 1.25 or lower. You can do this by running the following command in a code cell:\n\n```\n!pip install numpy==1.25\n```\n\nAfter downgrading NumPy, you can try running your code again to see if the error is resolved.","date":"2023-10-10T21:25:16.063Z"}],"reply_to":"2023-10-10T21:25:16.057Z","sender_id":"chatgpt"}
{"date":"2023-10-10T21:25:48.492Z","event":"chat","history":[{"author_id":"d9218c0f-616b-453d-85a3-dcbe9ee8ddba","content":"<span class=\"user-mention\" account-id=chatgpt>@ChatGPT</span> help me fix my code.\n\n<details><summary>Context</summary>\n\n\nI ran a cell in a Jupyter notebook.\n\nI received the following error:\n\n```python\n---------------------------------------------------------------------------\nImportError                               Traceback (most recent call last)\nCell In[6], line 1\n----> 1 from bertopic.representation import KeyBERTInspired\n      2 from bertopic.representation import PartOfSpeech\n      3 from bertopic.representation import MaximalMarginalRelevance\n\nFile ~/.local/lib/python3.10/site-packages/bertopic/__init__.py:1\n----> 1 from bertopic._bertopic import BERTopic\n      3 __version__ = \"0.15.0\"\n      5 __all__ = [\n      6     \"BERTopic\",\n      7 ]\n\nFile ~/.local/lib/python3.10/site-packages/bertopic/_bertopic.py:38\n     36 # Models\n     37 import hdbscan\n---> 38 from umap import UMAP\n     39 from sklearn.preprocessing import normalize\n     40 from sklearn import __version__ as sklearn_version\n\nFile ~/.local/lib/python3.10/site-packages/umap/__init__.py:2\n      1 from warnings import warn, catch_warnings, simplefilter\n----> 2 from .umap_ import UMAP\n      4 try:\n      5     with catch_warnings():\n\nFile ~/.local/lib/python3.10/site-packages/umap/umap_.py:29\n     27 from scipy.sparse import tril as sparse_tril, triu as sparse_triu\n     28 import scipy.sparse.csgraph\n---> 29 import numba\n     31 import umap.distances as dist\n     33 import umap.sparse as sparse\n\nFile ~/.local/lib/python3.10/site-packages/numba/__init__.py:55\n     50             msg = (\"Numba requires SciPy version 1.0 or greater. Got SciPy \"\n     51                    f\"{scipy.__version__}.\")\n     52             raise ImportError(msg)\n---> 55 _ensure_critical_deps()\n     56 # END DO NOT MOVE\n     57 # ---------------------- WARNING WARNING WARNING ----------------------------\n     60 from ._version import get_versions\n\nFile ~/.local/lib/python3.10/site-packages/numba/__init__.py:42, in _ensure_critical_deps()\n     40     raise ImportError(msg)\n     41 elif numpy_version > (1, 25):\n---> 42     raise ImportError(\"Numba needs NumPy 1.25 or less\")\n     43 try:\n     44     import scipy\n\nImportError: Numba needs NumPy 1.25 or less\n```\n\n\nMy Jupyter notebook using the Python 3 (Ubuntu Linux) kernel contains:\n\n```python\n\n\nfrom bertopic.representation import KeyBERTInspired\nfrom bertopic.representation import PartOfSpeech\nfrom bertopic.representation import MaximalMarginalRelevance\nfrom sklearn.datasets import fetch_20newsgroups\nimport pandas as pd  # Import pandas after reinstalling it\nfrom sklearn.model_selection import train_test_split\n```\n\n\n\n</details>","date":"2023-10-10T21:25:48.492Z"}],"sender_id":"d9218c0f-616b-453d-85a3-dcbe9ee8ddba"}
{"date":"2023-10-10T21:25:48.498Z","event":"chat","generating":false,"history":[{"author_id":"chatgpt","content":"The error message you received indicates that Numba needs NumPy version 1.25 or less. To fix this issue, you can try downgrading your NumPy version. Here's how you can do it:\n\n1. Open a terminal in your CoCalc project.\n\n2. Run the following command to uninstall the current version of NumPy:\n   ```\n   !pip uninstall numpy\n   ```\n\n3. Run the following command to install NumPy version 1.25:\n   ```\n   !pip install numpy==1.25\n   ```\n\n4. After installing the correct version of NumPy, try running your code again.\n\nIf downgrading NumPy doesn't solve the issue, you may need to check if there are any other conflicting dependencies in your environment.","date":"2023-10-10T21:25:48.498Z"}],"reply_to":"2023-10-10T21:25:48.492Z","sender_id":"chatgpt"}
{"date":"2023-10-10T22:47:55.801Z","event":"chat","history":[{"author_id":"d9218c0f-616b-453d-85a3-dcbe9ee8ddba","content":"<span class=\"user-mention\" account-id=chatgpt>@ChatGPT</span> help me fix my code.\n\n<details><summary>Context</summary>\n\n\nI ran a cell in a Jupyter notebook.\n\nI received the following error:\n\n```python\n---------------------------------------------------------------------------\nUnicodeDecodeError                        Traceback (most recent call last)\nCell In[5], line 2\n      1 # Documents to train on\n----> 2 df = pd.read_csv(\"10102023combined_and_shuffled_standards.xlsx\")\n      3 df = df.loc[(df.label == \"standard\")]\n      4 print(df.groupby(\"label\").count())\n\nFile ~/.local/lib/python3.10/site-packages/pandas/io/parsers/readers.py:948, in read_csv(filepath_or_buffer, sep, delimiter, header, names, index_col, usecols, dtype, engine, converters, true_values, false_values, skipinitialspace, skiprows, skipfooter, nrows, na_values, keep_default_na, na_filter, verbose, skip_blank_lines, parse_dates, infer_datetime_format, keep_date_col, date_parser, date_format, dayfirst, cache_dates, iterator, chunksize, compression, thousands, decimal, lineterminator, quotechar, quoting, doublequote, escapechar, comment, encoding, encoding_errors, dialect, on_bad_lines, delim_whitespace, low_memory, memory_map, float_precision, storage_options, dtype_backend)\n    935 kwds_defaults = _refine_defaults_read(\n    936     dialect,\n    937     delimiter,\n   (...)\n    944     dtype_backend=dtype_backend,\n    945 )\n    946 kwds.update(kwds_defaults)\n--> 948 return _read(filepath_or_buffer, kwds)\n--> 611 parser = TextFileReader(filepath_or_buffer, **kwds)\n-> 1448 self._engine = self._make_engine(f, self.engine)\n-> 1723     return mapping[engine](f, **self.options)\n---> 93 self._reader = parsers.TextReader(src, **kwds)\n     95 self.unnamed_cols = self._reader.unnamed_cols\n     97 # error: Cannot determine type of 'names'\n\nFile parsers.pyx:579, in pandas._libs.parsers.TextReader.__cinit__()\n\nFile parsers.pyx:668, in pandas._libs.parsers.TextReader._get_header()\n\nFile parsers.pyx:879, in pandas._libs.parsers.TextReader._tokenize_rows()\n\nFile parsers.pyx:890, in pandas._libs.parsers.TextReader._check_tokenize_status()\n\nFile parsers.pyx:2050, in pandas._libs.parsers.raise_parser_error()\n\nUnicodeDecodeError: 'utf-8' codec can't decode bytes in position 15-16: invalid continuation byte\n```\n\n\nMy Jupyter notebook using the Python 3 (Ubuntu Linux) kernel contains:\n\n```python\n# Documents to train on\ndf = pd.read_csv(\"10102023combined_and_shuffled_standards.xlsx\")\ndf = df.loc[(df.label == \"standard\")]\nprint(df.groupby(\"label\").count())\nprint(df.head())\nrequirements = df.text.tolist()\nlabels = df.label.map({'standard': 1, 'requirement': 0}).tolist()\n```\n\n\n\n</details>","date":"2023-10-10T22:47:55.801Z"}],"sender_id":"d9218c0f-616b-453d-85a3-dcbe9ee8ddba"}
{"date":"2023-10-10T22:47:55.807Z","event":"chat","generating":false,"history":[{"author_id":"chatgpt","content":"The error message suggests that there is a problem with the encoding of the file you are trying to read using `pd.read_csv()`. It seems that the file \"10102023combined_and_shuffled_standards.xlsx\" is not in the expected UTF-8 encoding.\n\nTo fix this issue, you can try specifying the correct encoding when reading the file. Replace the following line:\n\n```python\ndf = pd.read_csv(\"10102023combined_and_shuffled_standards.xlsx\")\n```\n\nwith\n\n```python\ndf = pd.read_csv(\"10102023combined_and_shuffled_standards.xlsx\", encoding=\"latin1\")\n```\n\nHere, we have specified the encoding parameter as \"latin1\", which is a common encoding for Excel files.\n\nAfter making this change, try running the cell again and see if the error is resolved.","date":"2023-10-10T22:47:55.807Z"}],"reply_to":"2023-10-10T22:47:55.801Z","sender_id":"chatgpt"}
{"date":"2023-10-10T22:50:09.514Z","event":"chat","history":[{"author_id":"d9218c0f-616b-453d-85a3-dcbe9ee8ddba","content":"<span class=\"user-mention\" account-id=chatgpt>@ChatGPT</span> help me fix my code.\n\n<details><summary>Context</summary>\n\n\nI ran a cell in a Jupyter notebook.\n\nI received the following error:\n\n```python\n---------------------------------------------------------------------------\nImportError                               Traceback (most recent call last)\nCell In[7], line 2\n      1 # Documents to train on\n----> 2 df = pd.read_excel(\"10102023combined_and_shuffled_standards.xlsx\")\n      3 df = df.loc[(df.label == \"standard\")]\n      4 print(df.groupby(\"label\").count())\n\nFile ~/.local/lib/python3.10/site-packages/pandas/io/excel/_base.py:504, in read_excel(io, sheet_name, header, names, index_col, usecols, dtype, engine, converters, true_values, false_values, skiprows, nrows, na_values, keep_default_na, na_filter, verbose, parse_dates, date_parser, date_format, thousands, decimal, comment, skipfooter, storage_options, dtype_backend, engine_kwargs)\n    502 if not isinstance(io, ExcelFile):\n    503     should_close = True\n--> 504     io = ExcelFile(\n    505         io,\n    506         storage_options=storage_options,\n    507         engine=engine,\n    508         engine_kwargs=engine_kwargs,\n    509     )\n    510 elif engine and engine != io.engine:\n    511     raise ValueError(\n    512         \"Engine should not be specified when passing \"\n    513         \"an ExcelFile - ExcelFile already has the engine set\"\n    514     )\n\nFile ~/.local/lib/python3.10/site-packages/pandas/io/excel/_base.py:1580, in ExcelFile.__init__(self, path_or_buffer, engine, storage_options, engine_kwargs)\n   1577 self.engine = engine\n   1578 self.storage_options = storage_options\n-> 1580 self._reader = self._engines[engine](\n   1581     self._io,\n   1582     storage_options=storage_options,\n   1583     engine_kwargs=engine_kwargs,\n   1584 )\n\nFile ~/.local/lib/python3.10/site-packages/pandas/io/excel/_openpyxl.py:552, in OpenpyxlReader.__init__(self, filepath_or_buffer, storage_options, engine_kwargs)\n    534 @doc(storage_options=_shared_docs[\"storage_options\"])\n    535 def __init__(\n    536     self,\n   (...)\n    539     engine_kwargs: dict | None = None,\n    540 ) -> None:\n    541     \"\"\"\n    542     Reader using openpyxl engine.\n    543 \n   (...)\n    550         Arbitrary keyword arguments passed to excel engine.\n    551     \"\"\"\n--> 552     import_optional_dependency(\"openpyxl\")\n    553     super().__init__(\n    554         filepath_or_buffer,\n    555         storage_options=storage_options,\n    556         engine_kwargs=engine_kwargs,\n    557     )\n\nFile ~/.local/lib/python3.10/site-packages/pandas/compat/_optional.py:161, in import_optional_dependency(name, extra, errors, min_version)\n    159             return None\n    160         elif errors == \"raise\":\n--> 161             raise ImportError(msg)\n    163 return module\n\nImportError: Pandas requires version '3.0.10' or newer of 'openpyxl' (version '3.0.9' currently installed).\n```\n\n\nMy Jupyter notebook using the Python 3 (Ubuntu Linux) kernel contains:\n\n```python\n# Documents to train on\ndf = pd.read_excel(\"10102023combined_and_shuffled_standards.xlsx\")\ndf = df.loc[(df.label == \"standard\")]\nprint(df.groupby(\"label\").count())\nprint(df.head())\nrequirements = df.text.tolist()\nlabels = df.label.map({'standard': 1, 'requirement': 0}).tolist()\n```\n\n\n\n</details>","date":"2023-10-10T22:50:09.514Z"}],"sender_id":"d9218c0f-616b-453d-85a3-dcbe9ee8ddba"}
{"date":"2023-10-10T22:50:09.520Z","event":"chat","generating":false,"history":[{"author_id":"chatgpt","content":"The error message indicates that your code is encountering an ImportError because the current version of openpyxl installed does not meet the required version of '3.0.10' or newer.\n\nTo fix this issue, you can try updating the openpyxl library to the required version.\n\nIn a code cell, execute the following command:\n\n```python\n!pip install openpyxl --upgrade\n```\n\nThis command will upgrade the openpyxl library to the latest version available.\n\nAfter that, you can rerun your code and it should work without encountering the ImportError.","date":"2023-10-10T22:50:09.520Z"}],"reply_to":"2023-10-10T22:50:09.514Z","sender_id":"chatgpt"}
{"date":"2023-10-10T22:51:07.606Z","event":"chat","history":[{"author_id":"d9218c0f-616b-453d-85a3-dcbe9ee8ddba","content":"<span class=\"user-mention\" account-id=chatgpt>@ChatGPT</span> help me fix my code.\n\n<details><summary>Context</summary>\n\n\nI ran a cell in a Jupyter notebook.\n\nI received the following error:\n\n```python\n---------------------------------------------------------------------------\nImportError                               Traceback (most recent call last)\nCell In[3], line 2\n      1 # Documents to train on\n----> 2 df = pd.read_excel(\"10102023combined_and_shuffled_standards.xlsx\")\n      3 df = df.loc[(df.label == \"standard\")]\n      4 print(df.groupby(\"label\").count())\n\nFile ~/.local/lib/python3.10/site-packages/pandas/io/excel/_base.py:504, in read_excel(io, sheet_name, header, names, index_col, usecols, dtype, engine, converters, true_values, false_values, skiprows, nrows, na_values, keep_default_na, na_filter, verbose, parse_dates, date_parser, date_format, thousands, decimal, comment, skipfooter, storage_options, dtype_backend, engine_kwargs)\n    502 if not isinstance(io, ExcelFile):\n    503     should_close = True\n--> 504     io = ExcelFile(\n    505         io,\n    506         storage_options=storage_options,\n    507         engine=engine,\n    508         engine_kwargs=engine_kwargs,\n    509     )\n    510 elif engine and engine != io.engine:\n    511     raise ValueError(\n    512         \"Engine should not be specified when passing \"\n    513         \"an ExcelFile - ExcelFile already has the engine set\"\n    514     )\n\nFile ~/.local/lib/python3.10/site-packages/pandas/io/excel/_base.py:1580, in ExcelFile.__init__(self, path_or_buffer, engine, storage_options, engine_kwargs)\n   1577 self.engine = engine\n   1578 self.storage_options = storage_options\n-> 1580 self._reader = self._engines[engine](\n   1581     self._io,\n   1582     storage_options=storage_options,\n   1583     engine_kwargs=engine_kwargs,\n   1584 )\n\nFile ~/.local/lib/python3.10/site-packages/pandas/io/excel/_openpyxl.py:552, in OpenpyxlReader.__init__(self, filepath_or_buffer, storage_options, engine_kwargs)\n    534 @doc(storage_options=_shared_docs[\"storage_options\"])\n    535 def __init__(\n    536     self,\n   (...)\n    539     engine_kwargs: dict | None = None,\n    540 ) -> None:\n    541     \"\"\"\n    542     Reader using openpyxl engine.\n    543 \n   (...)\n    550         Arbitrary keyword arguments passed to excel engine.\n    551     \"\"\"\n--> 552     import_optional_dependency(\"openpyxl\")\n    553     super().__init__(\n    554         filepath_or_buffer,\n    555         storage_options=storage_options,\n    556         engine_kwargs=engine_kwargs,\n    557     )\n\nFile ~/.local/lib/python3.10/site-packages/pandas/compat/_optional.py:161, in import_optional_dependency(name, extra, errors, min_version)\n    159             return None\n    160         elif errors == \"raise\":\n--> 161             raise ImportError(msg)\n    163 return module\n\nImportError: Pandas requires version '3.0.10' or newer of 'openpyxl' (version '3.0.9' currently installed).\n```\n\n\nMy Jupyter notebook using the Python 3 (Ubuntu Linux) kernel contains:\n\n```python\n# Documents to train on\ndf = pd.read_excel(\"10102023combined_and_shuffled_standards.xlsx\")\ndf = df.loc[(df.label == \"standard\")]\nprint(df.groupby(\"label\").count())\nprint(df.head())\nrequirements = df.text.tolist()\nlabels = df.label.map({'standard': 1, 'requirement': 0}).tolist()\n```\n\n\n\n</details>","date":"2023-10-10T22:51:07.606Z"}],"sender_id":"d9218c0f-616b-453d-85a3-dcbe9ee8ddba"}
{"date":"2023-10-10T22:51:07.612Z","event":"chat","generating":false,"history":[{"author_id":"chatgpt","content":"Based on the error message, it seems that the version of the `openpyxl` library installed on your system is older than the required version. \n\nTo fix this issue, you can try upgrading the `openpyxl` library to the required version by running the following command in a code cell:\n\n```python\n!pip install --upgrade openpyxl\n```\n\nMake sure to run this command before running the rest of your code. \n\nOnce you have upgraded the `openpyxl` library, you can rerun your code and the error should be resolved.","date":"2023-10-10T22:51:07.612Z"}],"reply_to":"2023-10-10T22:51:07.606Z","sender_id":"chatgpt"}
{"date":"2023-10-10T22:53:03.597Z","event":"chat","history":[{"author_id":"d9218c0f-616b-453d-85a3-dcbe9ee8ddba","content":"<span class=\"user-mention\" account-id=chatgpt>@ChatGPT</span> help me fix my code.\n\n<details><summary>Context</summary>\n\n\nI ran a cell in a Jupyter notebook.\n\nI received the following error:\n\n```python\n---------------------------------------------------------------------------\nNameError                                 Traceback (most recent call last)\nCell In[5], line 14\n      8 # Add all models together to be run in a single `fit`\n      9 representation_model = {\n     10    \"Main\": main_representation,\n     11    \"Aspect1\":  aspect_model1,\n     12    \"Aspect2\":  aspect_model2 \n     13 }\n---> 14 topic_model = BERTopic(representation_model=representation_model).fit(train_requs)\n\nNameError: name 'BERTopic' is not defined\n```\n\n\nMy Jupyter notebook using the Python 3 (Ubuntu Linux) kernel contains:\n\n```python\n\n# The main representation of a topic\nmain_representation = KeyBERTInspired()\n\n# Additional ways of representing a topic\naspect_model1 = PartOfSpeech(\"en_core_web_sm\")\naspect_model2 = [KeyBERTInspired(top_n_words=30), MaximalMarginalRelevance(diversity=.5)]\n\n# Add all models together to be run in a single `fit`\nrepresentation_model = {\n   \"Main\": main_representation,\n   \"Aspect1\":  aspect_model1,\n   \"Aspect2\":  aspect_model2 \n}\ntopic_model = BERTopic(representation_model=representation_model).fit(train_requs)\n\n```\n\n\n\n</details>","date":"2023-10-10T22:53:03.597Z"}],"sender_id":"d9218c0f-616b-453d-85a3-dcbe9ee8ddba"}
{"date":"2023-10-10T22:53:03.604Z","event":"chat","generating":false,"history":[{"author_id":"chatgpt","content":"The error message \"NameError: name 'BERTopic' is not defined\" suggests that the `BERTopic` class is not imported or defined in your code.\n\nTo fix this error, you need to import the `BERTopic` class from the appropriate module. You can try adding the following line at the beginning of your code:\n\n```python\nfrom bertopic import BERTopic\n```\n\nMake sure that you have the `bertopic` package installed in your environment. If it's not already installed, you can install it by running the following command in a code cell:\n\n```python\n!pip install bertopic\n```\n\nAfter making these changes, try running your code again to see if the error is resolved.","date":"2023-10-10T22:53:03.604Z"}],"reply_to":"2023-10-10T22:53:03.597Z","sender_id":"chatgpt"}
{"date":"2023-10-10T22:55:11.994Z","event":"chat","history":[{"author_id":"d9218c0f-616b-453d-85a3-dcbe9ee8ddba","content":"<span class=\"user-mention\" account-id=chatgpt>@ChatGPT</span> help me fix my code.\n\n<details><summary>Context</summary>\n\n\nI ran a cell in a Jupyter notebook.\n\nI received the following error:\n\n```python\n---------------------------------------------------------------------------\nTypeError                                 Traceback (most recent call last)\nCell In[8], line 1\n----> 1 topic_model.visualize_topics()\n\nFile ~/.local/lib/python3.10/site-packages/bertopic/_bertopic.py:2193, in BERTopic.visualize_topics(self, topics, top_n_topics, custom_labels, title, width, height)\n   2163 \"\"\" Visualize topics, their sizes, and their corresponding words\n   2164 \n   2165 This visualization is highly inspired by LDAvis, a great visualization\n   (...)\n   2190 ```\n   2191 \"\"\"\n   2192 check_is_fitted(self)\n-> 2193 return plotting.visualize_topics(self,\n   2194                                  topics=topics,\n   2195                                  top_n_topics=top_n_topics,\n-> 2887     self.fit(X, y, force_all_finite)\n-> 2780     self.embedding_, aux_data = self._fit_embed_data(\n-> 2826     return simplicial_set_embedding(\n-> 1106     embedding = spectral_layout(\n--> 304     return _spectral_layout(\n--> 521     eigenvalues, eigenvectors = scipy.sparse.linalg.eigsh(\n    531     with warnings.catch_warnings():\n\nFile /usr/local/lib/python3.10/dist-packages/scipy/sparse/linalg/_eigen/arpack/arpack.py:1605, in eigsh(A, k, M, sigma, which, v0, ncv, maxiter, tol, return_eigenvectors, Minv, OPinv, mode)\n   1600 warnings.warn(\"k >= N for N * N square matrix. \"\n   1601               \"Attempting to use scipy.linalg.eigh instead.\",\n   1602               RuntimeWarning)\n   1604 if issparse(A):\n-> 1605     raise TypeError(\"Cannot use scipy.linalg.eigh for sparse A with \"\n   1606                     \"k >= N. Use scipy.linalg.eigh(A.toarray()) or\"\n   1607                     \" reduce k.\")\n   1608 if isinstance(A, LinearOperator):\n   1609     raise TypeError(\"Cannot use scipy.linalg.eigh for LinearOperator \"\n   1610                     \"A with k >= N.\")\n\nTypeError: Cannot use scipy.linalg.eigh for sparse A with k >= N. Use scipy.linalg.eigh(A.toarray()) or reduce k.\n```\n\n\nMy Jupyter notebook using the Python 3 (Ubuntu Linux) kernel contains:\n\n```python\ntopic_model.visualize_topics()\n```\n\n\n\n</details>","date":"2023-10-10T22:55:11.994Z"}],"sender_id":"d9218c0f-616b-453d-85a3-dcbe9ee8ddba"}
{"date":"2023-10-10T22:55:12.000Z","event":"chat","generating":false,"history":[{"author_id":"chatgpt","content":"The error message indicates that the `visualize_topics()` method in your code is encountering a `TypeError` related to the use of sparse matrices with the `scipy.linalg.eigh()` function. \n\nTo fix this, you can try converting the sparse matrix to a dense array by using the `toarray()` method. Modify your code to:\n\n```python\ntopic_model.visualize_topics(topics=some_topics, top_n_topics=5)  # Replace 'some_topics' with the desired topics\n```\n\nMake sure to provide the appropriate topics or remove the argument entirely if you want to visualize all topics.","date":"2023-10-10T22:55:12.000Z"}],"reply_to":"2023-10-10T22:55:11.994Z","sender_id":"chatgpt"}
{"date":"2023-10-10T23:00:17.334Z","event":"chat","history":[{"author_id":"d9218c0f-616b-453d-85a3-dcbe9ee8ddba","content":"<span class=\"user-mention\" account-id=chatgpt>@ChatGPT</span> Explain the following Python 3 (Ubuntu Linux) code that is in a Jupyter notebook:\n\n<details>\n\n\n```python\n\n# The main representation of a topic\nmain_representation = KeyBERTInspired()\n\n# Additional ways of representing a topic\naspect_model1 = PartOfSpeech(\"en_core_web_sm\")\naspect_model2 = [KeyBERTInspired(top_n_words=30), MaximalMarginalRelevance(diversity=.5)]\n\n# Add all models together to be run in a single `fit`\nrepresentation_model = {\n   \"Main\": main_representation,\n   \"Aspect1\":  aspect_model1,\n   \"Aspect2\":  aspect_model2 \n}\ntopic_model = BERTopic(representation_model=representation_model).fit(train_requs)\n\n```\n\n\n</details>","date":"2023-10-10T23:00:17.334Z"}],"sender_id":"d9218c0f-616b-453d-85a3-dcbe9ee8ddba"}
{"date":"2023-10-10T23:00:17.340Z","event":"chat","generating":false,"history":[{"author_id":"chatgpt","content":"This Python code defines a topic modeling pipeline using the BERTopic library in Python 3, specifically for the Ubuntu Linux system. \n\n- The code first creates an instance of the `KeyBERTInspired` class called `main_representation`, which is the main representation of a topic.\n- It then creates additional ways of representing a topic:\n  - `aspect_model1` is an instance of the `PartOfSpeech` class, using the English language model `en_core_web_sm`.\n  - `aspect_model2` is a list containing two elements:\n    - An instance of the `KeyBERTInspired` class, with a parameter `top_n_words` set to 30.\n    - An instance of the `MaximalMarginalRelevance` class, with a parameter `diversity` set to 0.5.\n- Next, the code combines all the representation models together into a dictionary called `representation_model`:\n  - The `main_representation` is associated with the key `\"Main\"`.\n  - The `aspect_model1` is associated with the key `\"Aspect1\"`.\n  - The `aspect_model2` is associated with the key `\"Aspect2\"`.\n- Finally, the code creates an instance of the `BERTopic` class, with the `representation_model` parameter set to `representation_model`. It then fits the topic modeling pipeline to the data stored in `train_requs`.","date":"2023-10-10T23:00:17.340Z"}],"reply_to":"2023-10-10T23:00:17.334Z","sender_id":"chatgpt"}
{"date":"2023-10-10T23:03:00.968Z","event":"chat","history":[{"author_id":"d9218c0f-616b-453d-85a3-dcbe9ee8ddba","content":"<span class=\"user-mention\" account-id=chatgpt>@ChatGPT</span> Explain the following Python 3 (Ubuntu Linux) code that is in a Jupyter notebook:\n\n<details>\n\n\n```python\n\n# The main representation of a topic\nmain_representation = KeyBERTInspired()\n\n# Additional ways of representing a topic\naspect_model1 = PartOfSpeech(\"en_core_web_sm\")\naspect_model2 = [KeyBERTInspired(top_n_words=30), MaximalMarginalRelevance(diversity=.5)]\n\n# Add all models together to be run in a single `fit`\nrepresentation_model = {\n   \"Main\": main_representation,\n   \"Aspect1\":  aspect_model1,\n   \"Aspect2\":  aspect_model2 \n}\ntopic_model = BERTopic(representation_model=representation_model).fit(train_requs)\n\n```\n\n\n</details>","date":"2023-10-10T23:03:00.968Z"}],"sender_id":"d9218c0f-616b-453d-85a3-dcbe9ee8ddba"}
{"date":"2023-10-10T23:03:00.975Z","event":"chat","generating":false,"history":[{"author_id":"chatgpt","content":"This Python code is using the BERTopic library in Python 3 to perform topic modeling. Here is a breakdown of the code:\n\n1. The code defines three different models for representing a topic:\n   - `main_representation`: This is the main representation of a topic using the `KeyBERTInspired()` model.\n   - `aspect_model1`: This represents a topic using the Part-of-Speech tagging model `en_core_web_sm` from the Spacy library.\n   - `aspect_model2`: This is a list containing two models: `KeyBERTInspired(top_n_words=30)` which represents a topic using the KeyBERTInspired model with the top 30 words, and `MaximalMarginalRelevance(diversity=.5)` which adds diversity to the generated topics.\n\n2. The code creates a dictionary called `representation_model` that combines all the above models. The keys of the dictionary are the names of the models, and the values are the actual models.\n\n3. Finally, the code uses the `BERTopic` model from the BERTopic library and passes the `representation_model` as a parameter to the constructor. It then fits the model to the given training data `train_requs`.","date":"2023-10-10T23:03:00.975Z"}],"reply_to":"2023-10-10T23:03:00.968Z","sender_id":"chatgpt"}
{"date":"2023-10-10T23:03:22.973Z","event":"chat","history":[{"author_id":"d9218c0f-616b-453d-85a3-dcbe9ee8ddba","content":"how can i increase the number of topics generated","date":"2023-10-10T23:03:22.973Z"}],"reply_to":"2023-10-10T23:03:00.968Z","sender_id":"d9218c0f-616b-453d-85a3-dcbe9ee8ddba"}
{"date":"2023-10-10T23:03:22.979Z","event":"chat","generating":false,"history":[{"author_id":"chatgpt","content":"To increase the number of topics generated by the `BERTopic` model, you can modify the `n_topics` parameter when initializing the `BERTopic` object. By default, the `n_topics` parameter is set to 30, but you can increase it by passing a larger value. \n\nFor example, if you want to generate 50 topics instead of the default 30, you can modify the code as follows:\n\n```python\ntopic_model = BERTopic(representation_model=representation_model, n_topics=50).fit(train_requs)\n```\n\nBy changing the `n_topics` value, the `BERTopic` model will generate a higher number of topics during the fitting process.","date":"2023-10-10T23:03:22.979Z"}],"reply_to":"2023-10-10T23:03:00.968Z","sender_id":"chatgpt"}
{"date":"2023-10-10T23:23:39.041Z","event":"chat","history":[{"author_id":"d9218c0f-616b-453d-85a3-dcbe9ee8ddba","content":"<span class=\"user-mention\" account-id=chatgpt>@ChatGPT</span> Explain the following Python 3 (Ubuntu Linux) code that is in a Jupyter notebook:\n\n<details>\n\n\n```python\n# Calculate the topic distributions on a token-level\ntopic_distr, topic_token_distr = topic_model.approximate_distribution(test_requs, calculate_tokens=True)\n\n# Visualize the token-level distributions\ndf = topic_model.visualize_approximate_distribution(test_requs[1], topic_token_distr[1])\ndf\n\n```\n\n\n</details>","date":"2023-10-10T23:23:39.041Z"}],"sender_id":"d9218c0f-616b-453d-85a3-dcbe9ee8ddba"}
{"date":"2023-10-10T23:23:39.047Z","event":"chat","generating":false,"history":[{"author_id":"chatgpt","content":"This code calculates the topic distributions on a token-level using a topic model. It calls the `approximate_distribution` function of the `topic_model` object with the input `test_requs` and sets the `calculate_tokens` parameter to `True`. The result is stored in `topic_distr` and `topic_token_distr`.\n\nThen, it visualizes the token-level distributions for the second element in `test_requs`. It calls the `visualize_approximate_distribution` function of the `topic_model` object with `test_requs[1]` and `topic_token_distr[1]` as inputs. The resulting visualization is stored in the `df` variable, and it is then displayed in a Jupyter notebook cell.","date":"2023-10-10T23:23:39.047Z"}],"reply_to":"2023-10-10T23:23:39.041Z","sender_id":"chatgpt"}
{"date":"2023-10-10T23:34:32.271Z","event":"chat","history":[{"author_id":"d9218c0f-616b-453d-85a3-dcbe9ee8ddba","content":"<span class=\"user-mention\" account-id=chatgpt>@ChatGPT</span> help me fix my code.\n\n<details><summary>Context</summary>\n\n\nI ran a cell in a Jupyter notebook.\n\nI received the following error:\n\n```python\n---------------------------------------------------------------------------\nKeyError                                  Traceback (most recent call last)\nCell In[25], line 2\n      1 # or use one of the other topic representations, like KeyBERTInspired\n----> 2 keybert_topic_labels = {topic: \" | \".join(list(zip(*values))[0][:3]) for topic, values in topic_model.topic_aspects_[\"KeyBERT\"].items()}\n      3 topic_model.set_topic_labels(keybert_topic_labels)\n\nKeyError: 'KeyBERT'\n```\n\n\nMy Jupyter notebook using the Python 3 (Ubuntu Linux) kernel contains:\n\n```python\n# or use one of the other topic representations, like KeyBERTInspired\nkeybert_topic_labels = {topic: \" | \".join(list(zip(*values))[0][:3]) for topic, values in topic_model.topic_aspects_[\"KeyBERT\"].items()}\ntopic_model.set_topic_labels(keybert_topic_labels)\n```\n\n\n\n</details>","date":"2023-10-10T23:34:32.271Z"}],"sender_id":"d9218c0f-616b-453d-85a3-dcbe9ee8ddba"}
{"date":"2023-10-10T23:34:32.278Z","event":"chat","generating":false,"history":[{"author_id":"chatgpt","content":"The error message suggests that there is a KeyError on the line where you are trying to access the `\"KeyBERT\"` key in the `topic_model.topic_aspects_` dictionary. \n\nTo fix this, you should make sure that the `\"KeyBERT\"` key exists in the `topic_model.topic_aspects_` dictionary before trying to access its values. You can do this using the `in` operator or the `get()` method. \n\nHere's an example of how you can modify your code to handle this KeyError:\n\n```python\n# or use one of the other topic representations, like KeyBERTInspired\nif \"KeyBERT\" in topic_model.topic_aspects_:\n    keybert_topic_labels = {topic: \" | \".join(list(zip(*values))[0][:3]) for topic, values in topic_model.topic_aspects_[\"KeyBERT\"].items()}\n    topic_model.set_topic_labels(keybert_topic_labels)\nelse:\n    # Handle the case when \"KeyBERT\" key is not found in topic_model.topic_aspects_\n    # You can choose to skip this step or provide default values for topic labels\n    print(\"Topic representation 'KeyBERT' not found.\")\n```\n\nBy adding the `if` statement, you check if the `\"KeyBERT\"` key exists before accessing its values. If it doesn't exist, you can handle the situation accordingly.","date":"2023-10-10T23:34:32.278Z"}],"reply_to":"2023-10-10T23:34:32.271Z","sender_id":"chatgpt"}
{"date":"2023-10-10T23:35:27.446Z","event":"chat","history":[{"author_id":"d9218c0f-616b-453d-85a3-dcbe9ee8ddba","content":"Topic representation 'KeyBERT' not found.","date":"2023-10-10T23:35:27.446Z"}],"reply_to":"2023-10-10T23:34:32.271Z","sender_id":"d9218c0f-616b-453d-85a3-dcbe9ee8ddba"}
{"date":"2023-10-10T23:35:27.455Z","event":"chat","generating":false,"history":[{"author_id":"chatgpt","content":"If the message \"Topic representation 'KeyBERT' not found\" is being printed, it means that the key \"KeyBERT\" does not exist in the `topic_model.topic_aspects_` dictionary.\n\nIn this case, you have a few options to consider:\n\n1. Check the documentation or source code of the `topic_model` object to confirm if the \"KeyBERT\" key is expected to be present. If it is expected and not found, there could be an issue with the initialization or configuration of `topic_model`.\n\n2. If the \"KeyBERT\" key is not expected to be present, you can modify your code to handle this situation appropriately. For example, you can choose to skip this step or provide default values for the topic labels.\n\nIf you need further assistance, please provide more information about the `topic_model` object and how it is being created or initialized.","date":"2023-10-10T23:35:27.455Z"}],"reply_to":"2023-10-10T23:34:32.271Z","sender_id":"chatgpt"}
{"date":"2023-10-10T23:37:43.695Z","event":"chat","history":[{"author_id":"d9218c0f-616b-453d-85a3-dcbe9ee8ddba","content":"<span class=\"user-mention\" account-id=chatgpt>@ChatGPT</span> Explain the following Python 3 (Ubuntu Linux) code that is in a Jupyter notebook:\n\n<details>\n\n\n```python\n\n# The main representation of a topic\nmain_representation = KeyBERTInspired()\n# or use one of the other topic representations, like KeyBERTInspired\nkeybert_topic_labels = {topic: \" | \".join(list(zip(*values))[0][:3]) for topic, values in topic_model.topic_aspects_[\"KeyBERT\"].items()}\ntopic_model.set_topic_labels(keybert_topic_labels)\n\n# Additional ways of representing a topic\naspect_model1 = PartOfSpeech(\"en_core_web_sm\")\naspect_model2 = [KeyBERTInspired(top_n_words=30), MaximalMarginalRelevance(diversity=.5)]\n\n# Add all models together to be run in a single `fit`\nrepresentation_model = {\n   \"Main\": main_representation,\n   \"Aspect1\":  aspect_model1,\n   \"Aspect2\":  aspect_model2 \n}\ntopic_model = BERTopic(representation_model=representation_model).fit(train_requs)\n\n```\n\n\n</details>","date":"2023-10-10T23:37:43.695Z"}],"sender_id":"d9218c0f-616b-453d-85a3-dcbe9ee8ddba"}
{"date":"2023-10-10T23:37:43.701Z","event":"chat","generating":false,"history":[{"author_id":"chatgpt","content":"This Python code sets up a topic modeling framework using the BERTopic library in Python. \n\nFirst, it initializes the main representation model as `KeyBERTInspired()`. \n\nThen, it sets up additional ways of representing a topic by creating two aspect models: `aspect_model1` using the \"en_core_web_sm\" part-of-speech model, and `aspect_model2` as a combination of `KeyBERTInspired` and `MaximalMarginalRelevance`.\n\nNext, it creates a dictionary called `representation_model` that combines all the models, with the keys \"Main\", \"Aspect1\", and \"Aspect2\".\n\nFinally, it initializes the BERTopic model with the `representation_model` and fits it to the training data `train_requs`.","date":"2023-10-10T23:37:43.701Z"}],"reply_to":"2023-10-10T23:37:43.695Z","sender_id":"chatgpt"}
{"date":"2023-10-10T23:40:43.863Z","event":"chat","history":[{"author_id":"d9218c0f-616b-453d-85a3-dcbe9ee8ddba","content":"<span class=\"user-mention\" account-id=chatgpt>@ChatGPT</span> help me fix my code.\n\n<details><summary>Context</summary>\n\n\nI ran a cell in a Jupyter notebook.\n\nI received the following error:\n\n```python\n---------------------------------------------------------------------------\nKeyError                                  Traceback (most recent call last)\nCell In[7], line 4\n      2 main_representation = KeyBERTInspired()\n      3 # or use one of the other topic representations, like KeyBERTInspired\n----> 4 keybert_topic_labels = {topic: \" | \".join(list(zip(*values))[0][:3]) for topic, values in topic_model.topic_aspects_[\"KeyBERT\"].items()}\n      5 topic_model.set_topic_labels(keybert_topic_labels)\n      7 # Additional ways of representing a topic\n\nKeyError: 'KeyBERT'\n```\n\n\nMy Jupyter notebook using the Python 3 (Ubuntu Linux) kernel contains:\n\n```python\n\n# The main representation of a topic\nmain_representation = KeyBERTInspired()\n# or use one of the other topic representations, like KeyBERTInspired\nkeybert_topic_labels = {topic: \" | \".join(list(zip(*values))[0][:3]) for topic, values in topic_model.topic_aspects_[\"KeyBERT\"].items()}\ntopic_model.set_topic_labels(keybert_topic_labels)\n\n# Additional ways of representing a topic\naspect_model1 = PartOfSpeech(\"en_core_web_sm\")\naspect_model2 = [KeyBERTInspired(top_n_words=30), MaximalMarginalRelevance(diversity=.5)]\n\n# Add all models together to be run in a single `fit`\nrepresentation_model = {\n   \"Main\": main_representation,\n   \"Aspect1\":  aspect_model1,\n   \"Aspect2\":  aspect_model2 \n}\ntopic_model = BERTopic(representation_model=representation_model).fit(train_requs)\n\n```\n\n\n\n</details>","date":"2023-10-10T23:40:43.863Z"}],"sender_id":"d9218c0f-616b-453d-85a3-dcbe9ee8ddba"}
{"date":"2023-10-10T23:40:43.869Z","event":"chat","generating":false,"history":[{"author_id":"chatgpt","content":"The error `KeyError: 'KeyBERT'` indicates that the key `'KeyBERT'` is not present in the `topic_aspects_` dictionary. \n\nTo fix this error, you need to make sure that the key `'KeyBERT'` exists in the `topic_aspects_` dictionary. \n\nHere are a few steps you can take to fix the code:\n\n1. Make sure that the `BERTopic` class has been imported in your notebook.\n\n2. Check if the `topic_model.topic_aspects_` dictionary contains the key `'KeyBERT'` by printing the dictionary before line 4. Use the following code:\n\n   ```python\n   print(topic_model.topic_aspects_)\n   ```\n\n   If the key `'KeyBERT'` does not exist, you need to modify your code accordingly.\n\n3. If the key `'KeyBERT'` does exist, check if the values associated with `'KeyBERT'` are in the expected format. Specifically, ensure that the values are iterable and contain a tuple of pairs.\n\n   If the values are not in the expected format, you need to modify your code to ensure the correct format.\n\nPlease review these steps and make any necessary modifications to your code.","date":"2023-10-10T23:40:43.869Z"}],"reply_to":"2023-10-10T23:40:43.863Z","sender_id":"chatgpt"}
{"date":"2023-10-10T23:50:52.977Z","event":"chat","history":[{"author_id":"d9218c0f-616b-453d-85a3-dcbe9ee8ddba","content":"<span class=\"user-mention\" account-id=chatgpt>@ChatGPT</span> help me fix my code.\n\n<details><summary>Context</summary>\n\n\nI ran a cell in a Jupyter notebook.\n\nI received the following error:\n\n```python\n---------------------------------------------------------------------------\nNameError                                 Traceback (most recent call last)\nCell In[16], line 1\n----> 1 tree = topic_model.get_topic_tree(hierarchical_topics)\n      2 print(tree)\n\nNameError: name 'hierarchical_topics' is not defined\n```\n\n\nMy Jupyter notebook using the Python 3 (Ubuntu Linux) kernel contains:\n\n```python\ntree = topic_model.get_topic_tree(hierarchical_topics)\nprint(tree)\n```\n\n\n\n</details>","date":"2023-10-10T23:50:52.977Z"}],"sender_id":"d9218c0f-616b-453d-85a3-dcbe9ee8ddba"}
{"date":"2023-10-10T23:50:52.984Z","event":"chat","generating":false,"history":[{"author_id":"chatgpt","content":"The error message indicates that the variable 'hierarchical_topics' is not defined before it is used in the line `tree = topic_model.get_topic_tree(hierarchical_topics)`. To fix this, you need to make sure that the variable 'hierarchical_topics' has been defined and assigned a value before using it in that line.","date":"2023-10-10T23:50:52.984Z"}],"reply_to":"2023-10-10T23:50:52.977Z","sender_id":"chatgpt"}
{"date":"2023-10-10T23:55:43.111Z","event":"chat","history":[{"author_id":"d9218c0f-616b-453d-85a3-dcbe9ee8ddba","content":"<span class=\"user-mention\" account-id=chatgpt>@ChatGPT</span> help me fix my code.\n\n<details><summary>Context</summary>\n\n\nI ran a cell in a Jupyter notebook.\n\nI received the following error:\n\n```python\n---------------------------------------------------------------------------\nModuleNotFoundError                       Traceback (most recent call last)\nCell In[19], line 1\n----> 1 from keybert import KeyBERT\n      3 keybert_model = KeyBERT()  # Initialize the KeyBERT model\n      5 # Create a mapping of topics and their keywords\n\nModuleNotFoundError: No module named 'keybert'\n```\n\n\nMy Jupyter notebook using the Python 3 (Ubuntu Linux) kernel contains:\n\n```python\nfrom keybert import KeyBERT\n\nkeybert_model = KeyBERT()  # Initialize the KeyBERT model\n\n# Create a mapping of topics and their keywords\ntopic_labels = {}\nfor i, keywords in enumerate(keywords_topics):\n    topic_labels[i] = \" | \".join(keywords)\n\n# Set these topics as labels for your topic model\ntopic_model.set_topic_labels(topic_labels)\n```\n\n\n\n</details>","date":"2023-10-10T23:55:43.111Z"}],"sender_id":"d9218c0f-616b-453d-85a3-dcbe9ee8ddba"}
{"date":"2023-10-10T23:55:43.117Z","event":"chat","generating":false,"history":[{"author_id":"chatgpt","content":"The error message \"ModuleNotFoundError: No module named 'keybert'\" suggests that the `keybert` module is not installed in your Python environment. \n\nTo fix this issue, you need to install the `keybert` module in your Jupyter notebook's Python environment. \n\nYou can install the module by running the following command in a code cell:\n\n```python\n!pip install keybert\n```\n\nAfter installing the `keybert` module, you should be able to import it without any errors.","date":"2023-10-10T23:55:43.117Z"}],"reply_to":"2023-10-10T23:55:43.111Z","sender_id":"chatgpt"}
{"date":"2023-10-10T23:58:01.825Z","event":"chat","history":[{"author_id":"d9218c0f-616b-453d-85a3-dcbe9ee8ddba","content":"<span class=\"user-mention\" account-id=chatgpt>@ChatGPT</span> help me fix my code.\n\n<details><summary>Context</summary>\n\n\nI ran a cell in a Jupyter notebook.\n\nI received the following error:\n\n```python\n---------------------------------------------------------------------------\nAttributeError                            Traceback (most recent call last)\nCell In[22], line 6\n      3 keybert_model = KeyBERT()  # Initialize the KeyBERT model\n      5 topic_model = KeyBERT()\n----> 6 topics, probs = topic_model.fit_transform(train_requs)\n      7 hierarchical_topics = topic_model.hierarchical_topics(train_requs)\n      8 # Create a mapping of topics and their keywords\n\nAttributeError: 'KeyBERT' object has no attribute 'fit_transform'\n```\n\n\nMy Jupyter notebook using the Python 3 (Ubuntu Linux) kernel contains:\n\n```python\nfrom keybert import KeyBERT\n\nkeybert_model = KeyBERT()  # Initialize the KeyBERT model\n\ntopic_model = KeyBERT()\ntopics, probs = topic_model.fit_transform(train_requs)\nhierarchical_topics = topic_model.hierarchical_topics(train_requs)\n# Create a mapping of topics and their keywords\ntopic_labels = {}\nfor i, keywords in enumerate(hierarchical_topics):\n    topic_labels[i] = \" | \".join(keywords)\n\n# Set these topics as labels for your topic model\ntopic_model.set_topic_labels(topic_labels)\n```\n\n\n\n</details>","date":"2023-10-10T23:58:01.825Z"}],"sender_id":"d9218c0f-616b-453d-85a3-dcbe9ee8ddba"}
{"date":"2023-10-10T23:58:01.832Z","event":"chat","generating":true,"history":[{"author_id":"chatgpt","content":"The error you received indicates that the 'KeyBERT' object does not have\n\n<span style='color:#b71c1c'>disconnect</span>\n\n---\n\nOpenAI [status](https://status.openai.com) and [downdetector](https://downdetector.com/status/openai).","date":"2023-10-10T23:58:01.832Z"}],"reply_to":"2023-10-10T23:58:01.825Z","sender_id":"chatgpt"}
{"date":"2023-10-10T23:58:07.981Z","event":"chat","history":[{"author_id":"d9218c0f-616b-453d-85a3-dcbe9ee8ddba","content":"<span class=\"user-mention\" account-id=chatgpt>@ChatGPT</span> help me fix my code.\n\n<details><summary>Context</summary>\n\n\nI ran a cell in a Jupyter notebook.\n\nI received the following error:\n\n```python\n---------------------------------------------------------------------------\nAttributeError                            Traceback (most recent call last)\nCell In[22], line 6\n      3 keybert_model = KeyBERT()  # Initialize the KeyBERT model\n      5 topic_model = KeyBERT()\n----> 6 topics, probs = topic_model.fit_transform(train_requs)\n      7 hierarchical_topics = topic_model.hierarchical_topics(train_requs)\n      8 # Create a mapping of topics and their keywords\n\nAttributeError: 'KeyBERT' object has no attribute 'fit_transform'\n```\n\n\nMy Jupyter notebook using the Python 3 (Ubuntu Linux) kernel contains:\n\n```python\nfrom keybert import KeyBERT\n\nkeybert_model = KeyBERT()  # Initialize the KeyBERT model\n\ntopic_model = KeyBERT()\ntopics, probs = topic_model.fit_transform(train_requs)\nhierarchical_topics = topic_model.hierarchical_topics(train_requs)\n# Create a mapping of topics and their keywords\ntopic_labels = {}\nfor i, keywords in enumerate(hierarchical_topics):\n    topic_labels[i] = \" | \".join(keywords)\n\n# Set these topics as labels for your topic model\ntopic_model.set_topic_labels(topic_labels)\n```\n\n\n\n</details>","date":"2023-10-10T23:58:07.981Z"}],"sender_id":"d9218c0f-616b-453d-85a3-dcbe9ee8ddba"}
{"date":"2023-10-10T23:58:07.987Z","event":"chat","generating":false,"history":[{"author_id":"chatgpt","content":"The error message suggests that the `KeyBERT` object does not have an attribute called `fit_transform`.\n\nTo fix this issue, you should instantiate `KeyBERT()` with the `backend=\"distilbert-base-nli-mean-tokens\"` argument, as this is the model that supports the `fit_transform` method.\n\nHere's the updated code:\n\n```python\nfrom keybert import KeyBERT\n\nkeybert_model = KeyBERT(backend=\"distilbert-base-nli-mean-tokens\")  # Initialize the KeyBERT model\n\ntopic_model = KeyBERT(backend=\"distilbert-base-nli-mean-tokens\")\ntopics, probs = topic_model.fit_transform(train_requs)\nhierarchical_topics = topic_model.hierarchical_topics(train_requs)\n\n# Create a mapping of topics and their keywords\ntopic_labels = {}\nfor i, keywords in enumerate(hierarchical_topics):\n    topic_labels[i] = \" | \".join(keywords)\n\n# Set these topics as labels for your topic model\ntopic_model.set_topic_labels(topic_labels)\n```\n\nWith this change, the `fit_transform` method should be accessible, and the error should be resolved.","date":"2023-10-10T23:58:07.987Z"}],"reply_to":"2023-10-10T23:58:07.981Z","sender_id":"chatgpt"}
{"date":"2023-10-10T23:58:47.318Z","event":"chat","history":[{"author_id":"d9218c0f-616b-453d-85a3-dcbe9ee8ddba","content":"<span class=\"user-mention\" account-id=chatgpt>@ChatGPT</span> help me fix my code.\n\n<details><summary>Context</summary>\n\n\nI ran a cell in a Jupyter notebook.\n\nI received the following error:\n\n```python\n---------------------------------------------------------------------------\nTypeError                                 Traceback (most recent call last)\nCell In[23], line 3\n      1 from keybert import KeyBERT\n----> 3 keybert_model = KeyBERT(backend=\"distilbert-base-nli-mean-tokens\")  # Initialize the KeyBERT model\n      5 topic_model = KeyBERT(backend=\"distilbert-base-nli-mean-tokens\")\n      6 topics, probs = topic_model.fit_transform(train_requs)\n\nTypeError: KeyBERT.__init__() got an unexpected keyword argument 'backend'\n```\n\n\nMy Jupyter notebook using the Python 3 (Ubuntu Linux) kernel contains:\n\n```python\nfrom keybert import KeyBERT\n\nkeybert_model = KeyBERT(backend=\"distilbert-base-nli-mean-tokens\")  # Initialize the KeyBERT model\n\ntopic_model = KeyBERT(backend=\"distilbert-base-nli-mean-tokens\")\ntopics, probs = topic_model.fit_transform(train_requs)\nhierarchical_topics = topic_model.hierarchical_topics(train_requs)\n\n# Create a mapping of topics and their keywords\ntopic_labels = {}\nfor i, keywords in enumerate(hierarchical_topics):\n    topic_labels[i] = \" | \".join(keywords)\n\n# Set these topics as labels for your topic model\ntopic_model.set_topic_labels(topic_labels)\n```\n\n\n\n</details>","date":"2023-10-10T23:58:47.318Z"}],"sender_id":"d9218c0f-616b-453d-85a3-dcbe9ee8ddba"}
{"date":"2023-10-10T23:58:47.324Z","event":"chat","generating":false,"history":[{"author_id":"chatgpt","content":"The you encountered is due to using an incorrect keyword argument in the `KeyBERT` constructor. \n\nTo fix this issue, you need to replace `backend` with `model` when initializing the `KeyBERT` model.\n\nHere is the corrected code:\n\n```python\nfrom keybert import KeyBERT\n\nkeybert_model = KeyBERT(model=\"distilbert-base-nli-mean-tokens\")  # Initialize the KeyBERT model\n\ntopic_model = KeyBERT(model=\"distilbert-base-nli-mean-tokens\")\ntopics, probs = topic_model.fit_transform(train_requs)\nhierarchical_topics = topic_model.hierarchical_topics(train_requs)\n\n# Create a mapping of topics and their keywords\ntopic_labels = {}\nfor i, keywords in enumerate(hierarchical_topics):\n    topic_labels[i] = \" | \".join(keywords)\n\n# Set these topics as labels for your topic model\ntopic_model.set_topic_labels(topic_labels)\n```\n\nMake sure you have the `keybert` library installed. You can install it by running `!pip install keybert` in a code cell before running the code.","date":"2023-10-10T23:58:47.324Z"}],"reply_to":"2023-10-10T23:58:47.318Z","sender_id":"chatgpt"}
{"date":"2023-10-10T23:59:16.874Z","event":"chat","history":[{"author_id":"d9218c0f-616b-453d-85a3-dcbe9ee8ddba","content":"<span class=\"user-mention\" account-id=chatgpt>@ChatGPT</span> help me fix my code.\n\n<details><summary>Context</summary>\n\n\nI ran a cell in a Jupyter notebook.\n\nI received the following error:\n\n```python\n---------------------------------------------------------------------------\nAttributeError                            Traceback (most recent call last)\nCell In[24], line 6\n      3 keybert_model = KeyBERT(model=\"distilbert-base-nli-mean-tokens\")  # Initialize the KeyBERT model\n      5 topic_model = KeyBERT(model=\"distilbert-base-nli-mean-tokens\")\n----> 6 topics, probs = topic_model.fit_transform(train_requs)\n      7 hierarchical_topics = topic_model.hierarchical_topics(train_requs)\n      9 # Create a mapping of topics and their keywords\n\nAttributeError: 'KeyBERT' object has no attribute 'fit_transform'\n```\n\n\nMy Jupyter notebook using the Python 3 (Ubuntu Linux) kernel contains:\n\n```python\nfrom keybert import KeyBERT\n\nkeybert_model = KeyBERT(model=\"distilbert-base-nli-mean-tokens\")  # Initialize the KeyBERT model\n\ntopic_model = KeyBERT(model=\"distilbert-base-nli-mean-tokens\")\ntopics, probs = topic_model.fit_transform(train_requs)\nhierarchical_topics = topic_model.hierarchical_topics(train_requs)\n\n# Create a mapping of topics and their keywords\ntopic_labels = {}\nfor i, keywords in enumerate(hierarchical_topics):\n    topic_labels[i] = \" | \".join(keywords)\n\n# Set these topics as labels for your topic model\ntopic_model.set_topic_labels(topic_labels)\n```\n\n\n\n</details>","date":"2023-10-10T23:59:16.874Z"}],"sender_id":"d9218c0f-616b-453d-85a3-dcbe9ee8ddba"}
{"date":"2023-10-10T23:59:16.880Z","event":"chat","generating":false,"history":[{"author_id":"chatgpt","content":"It that the error is caused by the `KeyBERT` object not having the `fit_transform` attribute. To fix this, you can change line 6 to use the `keybert_model` instead of the `topic_model`:\n\n```python\ntopics, probs = keybert_model.fit_transform(train_requs)\n```\n\nMake sure to update the variable name consistently throughout your code.","date":"2023-10-10T23:59:16.880Z"}],"reply_to":"2023-10-10T23:59:16.874Z","sender_id":"chatgpt"}
{"date":"2023-10-11T00:01:01.127Z","event":"chat","history":[{"author_id":"d9218c0f-616b-453d-85a3-dcbe9ee8ddba","content":"<span class=\"user-mention\" account-id=chatgpt>@ChatGPT</span> help me fix my code.\n\n<details><summary>Context</summary>\n\n\nI ran a cell in a Jupyter notebook.\n\nI received the following error:\n\n```python\n  Cell In[25], line 6\n    topics, probs = keybert_model.fit_transform(train_requs)keybert_model.fit_transform(train_requs)\n                                                            ^\nSyntaxError: invalid syntax\n```\n\n\nMy Jupyter notebook using the Python 3 (Ubuntu Linux) kernel contains:\n\n```python\nfrom keybert import KeyBERT\n\nkeybert_model = KeyBERT(model=\"distilbert-base-nli-mean-tokens\")  # Initialize the KeyBERT model\n\ntopic_model = KeyBERT(model=\"distilbert-base-nli-mean-tokens\")\ntopics, probs = keybert_model.fit_transform(train_requs)keybert_model.fit_transform(train_requs)\nhierarchical_topics = topic_model.hierarchical_topics(train_requs)\n\n# Create a mapping of topics and their keywords\ntopic_labels = {}\nfor i, keywords in enumerate(hierarchical_topics):\n    topic_labels[i] = \" | \".join(keywords)\n\n# Set these topics as labels for your topic model\ntopic_model.set_topic_labels(topic_labels)\n```\n\n\n\n</details>","date":"2023-10-11T00:01:01.127Z"}],"sender_id":"d9218c0f-616b-453d-85a3-dcbe9ee8ddba"}
{"date":"2023-10-11T00:01:01.133Z","event":"chat","generating":false,"history":[{"author_id":"chatgpt","content":"The error you received is a \"SyntaxError: invalid syntax\" error. It is pointing to the line that says:\n\n```python\ntopics, probs = keybert_model.fit_transform(train_requs)keybert_model.fit_transform(train_requs)\n```\n\nThe issue here is that there is a missing semicolon (;) between the two calls to `fit_transform()`.\n\nTo fix this error, you need to add a semicolon (;) between the two calls, like this:\n\n```python\ntopics, probs = keybert_model.fit_transform(train_requs); keybert_model.fit_transform(train_requs)\n```\n\nAfter making this change, the code should run without any syntax errors.","date":"2023-10-11T00:01:01.133Z"}],"reply_to":"2023-10-11T00:01:01.127Z","sender_id":"chatgpt"}
{"date":"2023-10-11T00:01:28.257Z","event":"chat","history":[{"author_id":"d9218c0f-616b-453d-85a3-dcbe9ee8ddba","content":"<span class=\"user-mention\" account-id=chatgpt>@ChatGPT</span> help me fix my code.\n\n<details><summary>Context</summary>\n\n\nI ran a cell in a Jupyter notebook.\n\nI received the following error:\n\n```python\n---------------------------------------------------------------------------\nAttributeError                            Traceback (most recent call last)\nCell In[26], line 6\n      3 keybert_model = KeyBERT(model=\"distilbert-base-nli-mean-tokens\")  # Initialize the KeyBERT model\n      5 topic_model = KeyBERT(model=\"distilbert-base-nli-mean-tokens\")\n----> 6 topics, probs = keybert_model.fit_transform(train_requs); keybert_model.fit_transform(train_requs)\n      7 hierarchical_topics = topic_model.hierarchical_topics(train_requs)\n      9 # Create a mapping of topics and their keywords\n\nAttributeError: 'KeyBERT' object has no attribute 'fit_transform'\n```\n\n\nMy Jupyter notebook using the Python 3 (Ubuntu Linux) kernel contains:\n\n```python\nfrom keybert import KeyBERT\n\nkeybert_model = KeyBERT(model=\"distilbert-base-nli-mean-tokens\")  # Initialize the KeyBERT model\n\ntopic_model = KeyBERT(model=\"distilbert-base-nli-mean-tokens\")\ntopics, probs = keybert_model.fit_transform(train_requs); keybert_model.fit_transform(train_requs)\nhierarchical_topics = topic_model.hierarchical_topics(train_requs)\n\n# Create a mapping of topics and their keywords\ntopic_labels = {}\nfor i, keywords in enumerate(hierarchical_topics):\n    topic_labels[i] = \" | \".join(keywords)\n\n# Set these topics as labels for your topic model\ntopic_model.set_topic_labels(topic_labels)\n```\n\n\n\n</details>","date":"2023-10-11T00:01:28.257Z"}],"sender_id":"d9218c0f-616b-453d-85a3-dcbe9ee8ddba"}
{"date":"2023-10-11T00:01:28.263Z","event":"chat","generating":false,"history":[{"author_id":"chatgpt","content":"It seems that you are using the `KeyBERT` library in your code, but you are getting an `AttributeError` stating that the 'KeyBERT' object has no attribute 'fit_transform'. \n\nThe issue is that the `KeyBERT` library does not have a `fit_transform` method. It seems like you may have mistakenly duplicated the line `keybert_model.fit_transform(train_requs); keybert_model.fit_transform(train_requs)`.\n\nTo fix this error, you can remove the duplicated line `keybert_model.fit_transform(train_requs); keybert_model.fit_transform(train_requs)` from your code. \n\nHere's the updated code:\n\n```python\nfrom keybert import KeyBERT\n\nkeybert_model = KeyBERT(model=\"distilbert-base-nli-mean-tokens\")  # Initialize the KeyBERT model\n\ntopic_model = KeyBERT(model=\"distilbert-base-nli-mean-tokens\")\ntopics, probs = keybert_model.fit_transform(train_requs)\nhierarchical_topics = topic_model.hierarchical_topics(train_requs)\n\n# Create a mapping of topics and their keywords\ntopic_labels = {}\nfor i, keywords in enumerate(hierarchical_topics):\n    topic_labels[i] = \" | \".join(keywords)\n\n# Set these topics as labels for your topic model\ntopic_model.set_topic_labels(topic_labels)\n```\n\nThis should resolve the `AttributeError` and prevent the duplicated method call.","date":"2023-10-11T00:01:28.263Z"}],"reply_to":"2023-10-11T00:01:28.257Z","sender_id":"chatgpt"}
{"date":"2023-10-11T00:01:56.924Z","event":"chat","history":[{"author_id":"d9218c0f-616b-453d-85a3-dcbe9ee8ddba","content":"<span class=\"user-mention\" account-id=chatgpt>@ChatGPT</span> help me fix my code.\n\n<details><summary>Context</summary>\n\n\nI ran a cell in a Jupyter notebook.\n\nI received the following error:\n\n```python\n---------------------------------------------------------------------------\nAttributeError                            Traceback (most recent call last)\nCell In[27], line 6\n      3 keybert_model = KeyBERT(model=\"distilbert-base-nli-mean-tokens\")  # Initialize the KeyBERT model\n      5 topic_model = KeyBERT(model=\"distilbert-base-nli-mean-tokens\")\n----> 6 topics, probs = keybert_model.fit_transform(train_requs)\n      7 hierarchical_topics = topic_model.hierarchical_topics(train_requs)\n      9 # Create a mapping of topics and their keywords\n\nAttributeError: 'KeyBERT' object has no attribute 'fit_transform'\n```\n\n\nMy Jupyter notebook using the Python 3 (Ubuntu Linux) kernel contains:\n\n```python\nfrom keybert import KeyBERT\n\nkeybert_model = KeyBERT(model=\"distilbert-base-nli-mean-tokens\")  # Initialize the KeyBERT model\n\ntopic_model = KeyBERT(model=\"distilbert-base-nli-mean-tokens\")\ntopics, probs = keybert_model.fit_transform(train_requs)\nhierarchical_topics = topic_model.hierarchical_topics(train_requs)\n\n# Create a mapping of topics and their keywords\ntopic_labels = {}\nfor i, keywords in enumerate(hierarchical_topics):\n    topic_labels[i] = \" | \".join(keywords)\n\n# Set these topics as labels for your topic model\ntopic_model.set_topic_labels(topic_labels)\n```\n\n\n\n</details>","date":"2023-10-11T00:01:56.924Z"}],"sender_id":"d9218c0f-616b-453d-85a3-dcbe9ee8ddba"}
{"date":"2023-10-11T00:01:56.930Z","event":"chat","generating":false,"history":[{"author_id":"chatgpt","content":"The error message indicates that the 'KeyBERT' object does not have an attribute called 'fit_transform.' To fix this error, you should replace the line `topics, probs = keybert_model.fit_transform(train_requs)` with `topics, probs = keybert_model.extract_keywords(train_requs)`. \n\nIn the `keybert_model.fit_transform` method, you should change `fit_transform` to `extract_keywords`. \n\nAfter making this change, your code should look like:\n\n```python\nfrom keybert import KeyBERT\n\nkeybert_model = KeyBERT(model=\"distilbert-base-nli-mean-tokens\")  # Initialize the KeyBERT model\n\ntopic_model = KeyBERT(model=\"distilbert-base-nli-mean-tokens\")\ntopics, probs = keybert_model.extract_keywords(train_requs)\nhierarchical_topics = topic_model.hierarchical_topics(train_requs)\n\n# Create a mapping of topics and their keywords\ntopic_labels = {}\nfor i, keywords in enumerate(hierarchical_topics):\n    topic_labels[i] = \" | \".join(keywords)\n\n# Set these topics as labels for your topic model\ntopic_model.set_topic_labels(topic_labels)\n```\n\nNow, the code should run without any AttributeError.","date":"2023-10-11T00:01:56.930Z"}],"reply_to":"2023-10-11T00:01:56.924Z","sender_id":"chatgpt"}
{"date":"2023-10-11T00:02:28.947Z","event":"chat","history":[{"author_id":"d9218c0f-616b-453d-85a3-dcbe9ee8ddba","content":"<span class=\"user-mention\" account-id=chatgpt>@ChatGPT</span> help me fix my code.\n\n<details><summary>Context</summary>\n\n\nI ran a cell in a Jupyter notebook.\n\nI received the following error:\n\n```python\n---------------------------------------------------------------------------\nValueError                                Traceback (most recent call last)\nCell In[28], line 6\n      3 keybert_model = KeyBERT(model=\"distilbert-base-nli-mean-tokens\")  # Initialize the KeyBERT model\n      5 topic_model = KeyBERT(model=\"distilbert-base-nli-mean-tokens\")\n----> 6 topics, probs = keybert_model.extract_keywords(train_requs)\n      7 hierarchical_topics = topic_model.hierarchical_topics(train_requs)\n      9 # Create a mapping of topics and their keywords\n\nValueError: too many values to unpack (expected 2)\n```\n\n\nMy Jupyter notebook using the Python 3 (Ubuntu Linux) kernel contains:\n\n```python\nfrom keybert import KeyBERT\n\nkeybert_model = KeyBERT(model=\"distilbert-base-nli-mean-tokens\")  # Initialize the KeyBERT model\n\ntopic_model = KeyBERT(model=\"distilbert-base-nli-mean-tokens\")\ntopics, probs = keybert_model.extract_keywords(train_requs)\nhierarchical_topics = topic_model.hierarchical_topics(train_requs)\n\n# Create a mapping of topics and their keywords\ntopic_labels = {}\nfor i, keywords in enumerate(hierarchical_topics):\n    topic_labels[i] = \" | \".join(keywords)\n\n# Set these topics as labels for your topic model\ntopic_model.set_topic_labels(topic_labels)\n```\n\n\n\n</details>","date":"2023-10-11T00:02:28.947Z"}],"sender_id":"d9218c0f-616b-453d-85a3-dcbe9ee8ddba"}
{"date":"2023-10-11T00:02:28.953Z","event":"chat","generating":false,"history":[{"author_id":"chatgpt","content":"The error message \"ValueError: too many values to unpack (expected 2)\" indicates that the variable `probs` is expecting to receive two values, but the `keybert_model.extract_keywords(train_requs)` function is returning more or fewer than two values.\n\nTo fix this issue, you need to check the documentation of `keybert_model.extract_keywords()` to see what it should return. Make sure that `train_requs` is the correct input for the function and that you're properly handling the returned values.\n\nIf you don't need the second value and only need `topics`, you can modify the line to:\n\n```python\ntopics = keybert_model.extract_keywords(train_requs)[0]\n```\n\nThis will assign the first value returned by `keybert_model.extract_keywords(train_requs)` to the variable `topics`.\n\nIf you need both `topics` and `probs`, but the function is not returning them as expected, you should investigate further and check if the model or input is causing the issue.","date":"2023-10-11T00:02:28.953Z"}],"reply_to":"2023-10-11T00:02:28.947Z","sender_id":"chatgpt"}
{"date":"2023-10-11T00:20:15.256Z","event":"chat","history":[{"author_id":"d9218c0f-616b-453d-85a3-dcbe9ee8ddba","content":"<span class=\"user-mention\" account-id=chatgpt>@ChatGPT</span> help me fix my code.\n\n<details><summary>Context</summary>\n\n\nI ran a cell in a Jupyter notebook.\n\nI received the following error:\n\n```python\n---------------------------------------------------------------------------\nValueError                                Traceback (most recent call last)\nCell In[10], line 7\n      5 topic_labels = []\n      6 for topic_tokens in topic_token_distr:\n----> 7     if topic_tokens:\n      8         # Select the token with the highest weight for the topic\n      9         top_token = max(topic_tokens, key=topic_tokens.get)\n     10         topic_labels.append(top_token)\n\nValueError: The truth value of an array with more than one element is ambiguous. Use a.any() or a.all()\n```\n\n\nMy Jupyter notebook using the Python 3 (Ubuntu Linux) kernel contains:\n\n```python\n# Calculate the topic distributions on a token-level and get the most important token as the label\ntopic_distr, topic_token_distr = topic_model.approximate_distribution(train_requs, calculate_tokens=True)\n\n# Extract the most important token as the label for each topic\ntopic_labels = []\nfor topic_tokens in topic_token_distr:\n    if topic_tokens:\n        # Select the token with the highest weight for the topic\n        top_token = max(topic_tokens, key=topic_tokens.get)\n        topic_labels.append(top_token)\n    else:\n        # Handle cases where there are no tokens for the topic\n        topic_labels.append(\"No tokens found\")\n\n# Now, topic_labels contains the most important token as the label for each topic\nfor label in topic_labels:\n    print(label)\n\n```\n\n\n\n</details>","date":"2023-10-11T00:20:15.256Z"}],"sender_id":"d9218c0f-616b-453d-85a3-dcbe9ee8ddba"}
{"date":"2023-10-11T00:20:15.263Z","event":"chat","generating":false,"history":[{"author_id":"chatgpt","content":"The error message indicates that the truth value of an array with more than one element is ambiguous. To fix this issue, you can modify the code as follows:\n\n```python\n# Calculate the topic distributions on a token-level and get the most important token as the label\ntopic_distr, topic_token_distr = topic_model.approximate_distribution(train_requs, calculate_tokens=True)\n\n# Extract the most important token as the label for each topic\ntopic_labels = []\nfor topic_tokens in topic_token_distr:\n    if len(topic_tokens) > 0:\n        # Select the token with the highest weight for the topic\n        top_token = max(topic_tokens, key=topic_tokens.get)\n        topic_labels.append(top_token)\n    else:\n        # Handle cases where there are no tokens for the topic\n        topic_labels.append(\"No tokens found\")\n\n# Now, topic_labels contains the most important token as the label for each topic\nfor label in topic_labels:\n    print(label)\n```\n\nBy using `len(topic_tokens) > 0` instead of `if topic_tokens`, you are checking if the topic_tokens list has more than 0 elements and thus avoiding the ambiguous truth value error.","date":"2023-10-11T00:20:15.263Z"}],"reply_to":"2023-10-11T00:20:15.256Z","sender_id":"chatgpt"}
{"date":"2023-10-11T00:20:36.657Z","event":"chat","history":[{"author_id":"d9218c0f-616b-453d-85a3-dcbe9ee8ddba","content":"<span class=\"user-mention\" account-id=chatgpt>@ChatGPT</span> help me fix my code.\n\n<details><summary>Context</summary>\n\n\nI ran a cell in a Jupyter notebook.\n\nI received the following error:\n\n```python\n---------------------------------------------------------------------------\nAttributeError                            Traceback (most recent call last)\nCell In[11], line 9\n      6 for topic_tokens in topic_token_distr:\n      7     if len(topic_tokens) > 0:\n      8         # Select the token with the highest weight for the topic\n----> 9         top_token = max(topic_tokens, key=topic_tokens.get)\n     10         topic_labels.append(top_token)\n     11     else:\n     12         # Handle cases where there are no tokens for the topic\n\nAttributeError: 'numpy.ndarray' object has no attribute 'get'\n```\n\n\nMy Jupyter notebook using the Python 3 (Ubuntu Linux) kernel contains:\n\n```python\n# Calculate the topic distributions on a token-level and get the most important token as the label\ntopic_distr, topic_token_distr = topic_model.approximate_distribution(train_requs, calculate_tokens=True)\n\n# Extract the most important token as the label for each topic\ntopic_labels = []\nfor topic_tokens in topic_token_distr:\n    if len(topic_tokens) > 0:\n        # Select the token with the highest weight for the topic\n        top_token = max(topic_tokens, key=topic_tokens.get)\n        topic_labels.append(top_token)\n    else:\n        # Handle cases where there are no tokens for the topic\n        topic_labels.append(\"No tokens found\")\n\n# Now, topic_labels contains the most important token as the label for each topic\nfor label in topic_labels:\n    print(label)\n```\n\n\n\n</details>","date":"2023-10-11T00:20:36.657Z"}],"sender_id":"d9218c0f-616b-453d-85a3-dcbe9ee8ddba"}
{"date":"2023-10-11T00:20:36.663Z","event":"chat","generating":false,"history":[{"author_id":"chatgpt","content":"Based on the error message, it appears that the `topic_tokens` object is a numpy array instead of a dictionary. The `max()` function with `key=topic_tokens.get` is trying to access the `get()` method of the numpy array, which is not defined.\n\nTo fix this issue, you can convert `topic_tokens` from a numpy array to a dictionary using the `tolist()` method. Here's the modified code:\n\n```python\n# Calculate the topic distributions on a token-level and get the most important token as the label\ntopic_distr, topic_token_distr = topic_model.approximate_distribution(train_requs, calculate_tokens=True)\n\n# Extract the most important token as the label for each topic\ntopic_labels = []\nfor topic_tokens in topic_token_distr:\n    if len(topic_tokens) > 0:\n        # Convert numpy array to dictionary\n        topic_tokens_dict = topic_tokens.tolist()\n        # Select the token with the highest weight for the topic\n        top_token = max(topic_tokens_dict, key=topic_tokens_dict.get)\n        topic_labels.append(top_token)\n    else:\n        # Handle cases where there are no tokens for the topic\n        topic_labels.append(\"No tokens found\")\n\n# Now, topic_labels contains the most important token as the label for each topic\nfor label in topic_labels:\n    print(label)\n```\n\nBy converting `topic_tokens` to a dictionary using `tolist()`, you will be able to use the `get()` method and resolve the `AttributeError` issue.","date":"2023-10-11T00:20:36.663Z"}],"reply_to":"2023-10-11T00:20:36.657Z","sender_id":"chatgpt"}
{"date":"2023-10-11T00:30:10.730Z","event":"chat","history":[{"author_id":"d9218c0f-616b-453d-85a3-dcbe9ee8ddba","content":"<span class=\"user-mention\" account-id=chatgpt>@ChatGPT</span> help me fix my code.\n\n<details><summary>Context</summary>\n\n\nI ran a cell in a Jupyter notebook.\n\nI received the following error:\n\n```python\n---------------------------------------------------------------------------\nImportError                               Traceback (most recent call last)\nCell In[8], line 3\n      1 from sentence_transformers import models, SentencesDataset, SentenceTransformer\n      2 from bertopic import BERTopic\n----> 3 from bertopic.backend._sentencetransformers import KeyBERTInspired\n      4 from bertopic.backend._sentencetransformers import MaximalMarginalRelevance\n      6 # Define custom representation models\n\nImportError: cannot import name 'KeyBERTInspired' from 'bertopic.backend._sentencetransformers' (/projects/c7a1100d-10f9-4de1-b172-d38d7d09565f/.local/lib/python3.10/site-packages/bertopic/backend/_sentencetransformers.py)\n```\n\n\nMy Jupyter notebook using the Python 3 (Ubuntu Linux) kernel contains:\n\n```python\n\nfrom sentence_transformers import models, SentencesDataset, SentenceTransformer\nfrom bertopic import BERTopic\nfrom bertopic.backend._sentencetransformers import KeyBERTInspired\nfrom bertopic.backend._sentencetransformers import MaximalMarginalRelevance\n\n# Define custom representation models\nmain_representation = KeyBERTInspired(top_n_words=20)  # Adjust the number of top words\n\naspect_model1 = PartOfSpeech(\"en_core_web_sm\")  # Customize as needed\naspect_model2 = [KeyBERTInspired(top_n_words=10), MaximalMarginalRelevance(diversity=0.3)]  # Adjust settings\n\n# Modify representation_model\nrepresentation_model = {\n   \"Main\": main_representation,\n   \"Aspect1\":  aspect_model1,\n   \"Aspect2\":  aspect_model2 \n}\n\n# Create and fit the BERTopic model with the custom representation\ntopic_model = BERTopic(representation_model=representation_model).fit(train_requs)\n\n```\n\n\n\n</details>","date":"2023-10-11T00:30:10.730Z"}],"sender_id":"d9218c0f-616b-453d-85a3-dcbe9ee8ddba"}
{"date":"2023-10-11T00:30:10.737Z","event":"chat","generating":false,"history":[{"author_id":"chatgpt","content":"It appears that there is an import error in your code. The `ImportError` suggests that the name `KeyBERTInspired` cannot be imported from the `bertopic.backend._sentencetransformers` module.\n\nTo fix this, you can try the following steps:\n\n1. Make sure that the `bertopic` package is installed. You can install it by running `!pip install bertopic` in a code cell.\n\n2. Check the version of the `bertopic` package you have installed. If you have an older version, try upgrading it to the latest version by running `!pip install --upgrade bertopic` in a code cell.\n\n3. After installing or upgrading the `bertopic` package, try importing `KeyBERTInspired` again. If the issue persists, try restarting the kernel of your Jupyter notebook and running the code again.\n\n4. If none of the above steps work, double-check the documentation of the `bertopic` package or reach out to the package maintainer for further assistance.\n\nRemember to execute each step one by one and check if the issue is resolved before moving on to the next step.","date":"2023-10-11T00:30:10.737Z"}],"reply_to":"2023-10-11T00:30:10.730Z","sender_id":"chatgpt"}
{"date":"2023-10-11T01:08:43.543Z","event":"chat","history":[{"author_id":"d9218c0f-616b-453d-85a3-dcbe9ee8ddba","content":"<span class=\"user-mention\" account-id=chatgpt>@ChatGPT</span> Explain the following Python 3 (Ubuntu Linux) code that is in a Jupyter notebook:\n\n<details>\n\n\n```python\ntopic_model.get_topic_info()\n```\n\n\n</details>","date":"2023-10-11T01:08:43.543Z"}],"sender_id":"d9218c0f-616b-453d-85a3-dcbe9ee8ddba"}
{"date":"2023-10-11T01:08:43.549Z","event":"chat","generating":false,"history":[{"author_id":"chatgpt","content":"The code snippet is calling the `get_topic_info()` method on the `topic_model` object. This method likely returns information about the topics in the topic model.","date":"2023-10-11T01:08:43.549Z"}],"reply_to":"2023-10-11T01:08:43.543Z","sender_id":"chatgpt"}
{"date":"2023-10-11T01:09:03.624Z","event":"chat","history":[{"author_id":"d9218c0f-616b-453d-85a3-dcbe9ee8ddba","content":"i want to save the output of this into a csv file","date":"2023-10-11T01:09:03.624Z"}],"reply_to":"2023-10-11T01:08:43.543Z","sender_id":"d9218c0f-616b-453d-85a3-dcbe9ee8ddba"}
{"date":"2023-10-11T01:09:03.633Z","event":"chat","generating":false,"history":[{"author_id":"chatgpt","content":"To save the output of `get_topic_info()` to a CSV file, you can use the `pandas` library in Python. Here's an example of how to do it:\n\n```python\nimport pandas as pd\n\n# Call the get_topic_info() method and save the output\ntopic_info = topic_model.get_topic_info()\n\n# Convert the output to a pandas DataFrame\ndf = pd.DataFrame(topic_info)\n\n# Save the DataFrame to a CSV file\ndf.to_csv('topic_info.csv', index=False)\n```\n\nThis code will save the output of `get_topic_info()` to a file named `topic_info.csv` in the current directory. Each row of the CSV file will represent a topic, and the columns will contain the information associated with each topic.","date":"2023-10-11T01:09:03.633Z"}],"reply_to":"2023-10-11T01:08:43.543Z","sender_id":"chatgpt"}
{"date":"2023-10-11T01:10:06.102Z","event":"chat","history":[{"author_id":"d9218c0f-616b-453d-85a3-dcbe9ee8ddba","content":"<span class=\"user-mention\" account-id=chatgpt>@ChatGPT</span> Explain the following Python 3 (Ubuntu Linux) code that is in a Jupyter notebook:\n\n<details>\n\n\n```python\ntopic_model.get_document_info(train_requs)\n```\n\n\n</details>","date":"2023-10-11T01:10:06.102Z"}],"sender_id":"d9218c0f-616b-453d-85a3-dcbe9ee8ddba"}
{"date":"2023-10-11T01:10:06.110Z","event":"chat","generating":false,"history":[{"author_id":"chatgpt","content":"The code `topic_model.get_document_info(train_requs)` calls the `get_document_info()` function of the `topic_model` object, passing `train_requs` as an argument. This function is likely used to extract information or properties of the documents in the `train_requs` dataset. The specific implementation details and outputs of this function would depend on the definition of the `get_document_info()` function within the `topic_model` class or module.","date":"2023-10-11T01:10:06.110Z"}],"reply_to":"2023-10-11T01:10:06.102Z","sender_id":"chatgpt"}
{"date":"2023-10-11T01:10:22.994Z","event":"chat","history":[{"author_id":"d9218c0f-616b-453d-85a3-dcbe9ee8ddba","content":"i want to save this as a csv","date":"2023-10-11T01:10:22.994Z"}],"reply_to":"2023-10-11T01:10:06.102Z","sender_id":"d9218c0f-616b-453d-85a3-dcbe9ee8ddba"}
{"date":"2023-10-11T01:10:23.002Z","event":"chat","generating":false,"history":[{"author_id":"chatgpt","content":"To save the output of the `topic_model.get_document_info(train_requs)` function as a CSV file in Python 3, you can use the `to_csv()` method from the pandas library. Here's an example:\n\n```python\nimport pandas as pd\n\ndf = topic_model.get_document_info(train_requs)\ndf.to_csv('output.csv', index=False)\n```\n\nIn this code, `df` is a pandas DataFrame object that stores the output of the `get_document_info()` function. The `to_csv()` method is called on this DataFrame to save it as a CSV file named \"output.csv\" in the current working directory. The `index=False` argument is used to exclude the index column from the CSV file. Adjust the file path to save the CSV in a different location as desired.","date":"2023-10-11T01:10:23.002Z"}],"reply_to":"2023-10-11T01:10:06.102Z","sender_id":"chatgpt"}
{"date":"2023-10-11T18:21:21.327Z","event":"chat","history":[{"author_id":"d9218c0f-616b-453d-85a3-dcbe9ee8ddba","content":"<span class=\"user-mention\" account-id=chatgpt>@ChatGPT</span> help me fix my code.\n\n<details><summary>Context</summary>\n\n\nI ran a cell in a Jupyter notebook.\n\nI received the following error:\n\n```python\n---------------------------------------------------------------------------\nValueError                                Traceback (most recent call last)\nCell In[10], line 1\n----> 1 hierarchical_topics = topic_model.hierarchical_topics(docs)\n      2 tree = topic_model.get_topic_tree(hierarchical_topics)\n      3 print(tree)\n\nFile ~/.local/lib/python3.10/site-packages/bertopic/_bertopic.py:938, in BERTopic.hierarchical_topics(self, docs, linkage_function, distance_function)\n    936 # Calculate distance\n    937 embeddings = self.c_tf_idf_[self._outliers:]\n--> 938 X = distance_function(embeddings)\n    939 X = validate_distance_matrix(X, embeddings.shape[0])\n    941 # Use the 1-D condensed distance matrix as an input instead of the raw distance matrix\n\nFile ~/.local/lib/python3.10/site-packages/bertopic/_bertopic.py:931, in BERTopic.hierarchical_topics.<locals>.<lambda>(x)\n    881 \"\"\" Create a hierarchy of topics\n--> 931     distance_function = lambda x: 1 - cosine_similarity(x)\n-> 1393 X, Y = check_pairwise_arrays(X, Y)\n--> 146     X = Y = check_array(\n    161         estimator=estimator,\n    162     )\n\nFile /usr/local/lib/python3.10/dist-packages/sklearn/utils/validation.py:931, in check_array(array, accept_sparse, accept_large_sparse, dtype, order, copy, force_all_finite, ensure_2d, allow_nd, ensure_min_samples, ensure_min_features, estimator, input_name)\n    929     n_samples = _num_samples(array)\n    930     if n_samples < ensure_min_samples:\n--> 931         raise ValueError(\n    932             \"Found array with %d sample(s) (shape=%s) while a\"\n    933             \" minimum of %d is required%s.\"\n    934             % (n_samples, array.shape, ensure_min_samples, context)\n    935         )\n    937 if ensure_min_features > 0 and array.ndim == 2:\n    938     n_features = array.shape[1]\n\nValueError: Found array with 0 sample(s) (shape=(0, 85)) while a minimum of 1 is required by check_pairwise_arrays.\n```\n\n\nMy Jupyter notebook using the Python 3 (Ubuntu Linux) kernel contains:\n\n```python\nhierarchical_topics = topic_model.hierarchical_topics(docs)\ntree = topic_model.get_topic_tree(hierarchical_topics)\nprint(tree)\n```\n\n\n\n</details>","date":"2023-10-11T18:21:21.327Z"}],"sender_id":"d9218c0f-616b-453d-85a3-dcbe9ee8ddba"}
{"date":"2023-10-11T18:21:21.333Z","event":"chat","generating":false,"history":[{"author_id":"chatgpt","content":"It seems that there is an error in your code related to the `check_pairwise_arrays` function from the scikit-learn library. The error message is indicating that there is an array with 0 samples, while a minimum of 1 sample is required.\n\nTo fix this error, you need to ensure that the `docs` variable is a valid input with at least one sample. Make sure that `docs` is correctly defined and contains the data you intend to pass to the `topic_model.hierarchical_topics` function.\n\nIf you have already checked that `docs` is defined and contains data, there might be an issue with the specific implementation of the `topic_model` or the way it handles input data. In that case, you may need to review the documentation or reach out to the library's developers for further assistance.","date":"2023-10-11T18:21:21.333Z"}],"reply_to":"2023-10-11T18:21:21.327Z","sender_id":"chatgpt"}
{"date":"2023-10-11T18:21:55.183Z","event":"chat","history":[{"author_id":"d9218c0f-616b-453d-85a3-dcbe9ee8ddba","content":"what format should the model recieve the data in","date":"2023-10-11T18:21:55.183Z"}],"reply_to":"2023-10-11T18:21:21.327Z","sender_id":"d9218c0f-616b-453d-85a3-dcbe9ee8ddba"}
{"date":"2023-10-11T18:21:55.188Z","event":"chat","generating":false,"history":[{"author_id":"chatgpt","content":"The format of the data that the `topic_model.hierarchical_topics` function expects depends on the specific requirements of the BERTopic library you are using. \n\nIn general, BERTopic expects the input data to be a list of strings, where each string represents a document or a piece of text. The input data can be pre-processed, tokenized, or cleaned according to your specific needs before passing it to the `hierarchical_topics` function.\n\nMake sure that the `docs` variable is a list of strings, where each string represents a document. Here is an example of how you can prepare your data:\n\n```python\ndocs = [\n    \"This is the first document.\",\n    \"This document is the second document.\",\n    \"And this is the third one.\",\n    \"Is this the first document?\",\n]\n```\n\nEnsure that your `docs` variable follows a similar structure, with each item in the list being a string representing a document.\n\nRemember to consult the documentation of the specific BERTopic library you are using for more information on the input data requirements and any additional pre-processing steps that may be necessary.","date":"2023-10-11T18:21:55.188Z"}],"reply_to":"2023-10-11T18:21:21.327Z","sender_id":"chatgpt"}
{"date":"2023-10-26T01:51:21.151Z","event":"chat","history":[{"author_id":"d9218c0f-616b-453d-85a3-dcbe9ee8ddba","content":"<span class=\"user-mention\" account-id=chatgpt>@ChatGPT</span> Explain the following Python 3 (Ubuntu Linux) code that is in a Jupyter notebook:\n\n<details>\n\n\n```python\nfrom bertopic import BERTopic\nfrom hdbscan import HDBSCAN\n\nhdbscan_model = HDBSCAN(min_cluster_size=10, metric='euclidean', cluster_selection_method='eom', prediction_data=True)\ntopic_model = BERTopic(hdbscan_model=hdbscan_model)\n\n```\n\n\n</details>","date":"2023-10-26T01:51:21.151Z"}],"sender_id":"d9218c0f-616b-453d-85a3-dcbe9ee8ddba"}
{"date":"2023-10-26T01:51:21.162Z","event":"chat","generating":false,"history":[{"author_id":"chatgpt","content":"The code imports two libraries, `BERTopic` and `HDBSCAN`, which are used for topic modeling and clustering, respectively. \n\nIt creates an instance of the `HDBSCAN` class, specifying some parameters such as `min_cluster_size` (the minimum number of data points in a cluster) and the distance metric to use (`euclidean`). `cluster_selection_method` is set to `'eom'`, which stands for \"Excess of Mass\" and is a method for selecting the optimal number of clusters. `prediction_data` is set to `True`, which indicates that the model will be used for prediction.\n\nThe code then creates an instance of the `BERTopic` class and assigns the previously created `HDBSCAN` model to the `hdbscan_model` parameter. BERTopic is a topic modeling algorithm that leverages the BERT language model for document representation.","date":"2023-10-26T01:51:21.162Z"}],"reply_to":"2023-10-26T01:51:21.151Z","sender_id":"chatgpt"}
{"date":"2023-10-26T01:51:58.844Z","event":"chat","history":[{"author_id":"d9218c0f-616b-453d-85a3-dcbe9ee8ddba","content":"how should i change it to using cosine metric","date":"2023-10-26T01:51:58.844Z"}],"reply_to":"2023-10-26T01:51:21.151Z","sender_id":"d9218c0f-616b-453d-85a3-dcbe9ee8ddba"}
{"date":"2023-10-26T01:51:58.849Z","event":"chat","generating":false,"history":[{"author_id":"chatgpt","content":"To change the code to use the cosine metric instead of the euclidean metric, you need to modify the `metric` parameter value when creating the `HDBSCAN` model. Replace `'euclidean'` with `'cosine'` as shown below:\n\n```python\nhdbscan_model = HDBSCAN(min_cluster_size=10, metric='cosine', cluster_selection_method='eom', prediction_data=True)\n```\n\nThis change will configure the HDBSCAN model to use the cosine similarity metric for clustering instead of the euclidean distance metric.","date":"2023-10-26T01:51:58.849Z"}],"reply_to":"2023-10-26T01:51:21.151Z","sender_id":"chatgpt"}
{"date":"2023-10-26T01:52:34.002Z","event":"chat","history":[{"author_id":"d9218c0f-616b-453d-85a3-dcbe9ee8ddba","content":"<span class=\"user-mention\" account-id=chatgpt>@ChatGPT</span> Explain the following Python 3 (Ubuntu Linux) code that is in a Jupyter notebook:\n\n<details>\n\n\n```python\n\n# The main representation of a topic\nmain_representation = KeyBERTInspired()\n\n\n# Additional ways of representing a topic\naspect_model1 = PartOfSpeech(\"en_core_web_sm\")\naspect_model2 = [KeyBERTInspired(top_n_words=30), MaximalMarginalRelevance(diversity=.5)]\n\n# Add all models together to be run in a single `fit`\nrepresentation_model = {\n   \"Main\": main_representation,\n   \"Aspect1\":  aspect_model1,\n   \"Aspect2\":  aspect_model2 \n}\ntopic_model = BERTopic(representation_model=representation_model, hdbscan_model=hdbscan_model).fit(train_requs)\n\n```\n\n\n</details>","date":"2023-10-26T01:52:34.002Z"}],"sender_id":"d9218c0f-616b-453d-85a3-dcbe9ee8ddba"}
{"date":"2023-10-26T01:52:34.009Z","event":"chat","generating":false,"history":[{"author_id":"chatgpt","content":"This code snippet is written in Python 3 and is meant to be run in a Jupyter notebook. \n\nThe code defines a few variables and then creates an instance of a topic representation model called `main_representation` using the `KeyBERTInspired` class. \n\nIt then creates additional ways of representing a topic using two different models: `aspect_model1` which uses the `PartOfSpeech` class with the \"en_core_web_sm\" model, and `aspect_model2` which is a list containing an instance of `KeyBERTInspired` with a parameter `top_n_words` set to 30, and an instance of `MaximalMarginalRelevance` with a parameter `diversity` set to 0.5.\n\nThe code then combines all the representation models together in a dictionary called `representation_model`. The keys of the dictionary (\"Main\", \"Aspect1\", \"Aspect2\") represent the different models, and the values represent the corresponding model instances.\n\nFinally, the code creates a `BERTopic` model instance with the `representation_model` and `hdbscan_model` parameters and fits the model using the `train_requs` dataset.\n\nOverall, this code sets up and trains a topic modeling model using different representation models for different aspects of the topics.","date":"2023-10-26T01:52:34.009Z"}],"reply_to":"2023-10-26T01:52:34.002Z","sender_id":"chatgpt"}
{"date":"2023-10-26T01:53:26.820Z","event":"chat","history":[{"author_id":"d9218c0f-616b-453d-85a3-dcbe9ee8ddba","content":"<span class=\"user-mention\" account-id=chatgpt>@ChatGPT</span> Explain the following Python 3 (Ubuntu Linux) code that is in a Jupyter notebook:\n\n<details>\n\n\n```python\nhierarchical_topics = topic_model.hierarchical_topics(train_requs)\ntree = topic_model.get_topic_tree(hierarchical_topics)\nprint(tree)\n```\n\n\n</details>","date":"2023-10-26T01:53:26.820Z"}],"sender_id":"d9218c0f-616b-453d-85a3-dcbe9ee8ddba"}
{"date":"2023-10-26T01:53:26.829Z","event":"chat","generating":false,"history":[{"author_id":"chatgpt","content":"This code is using a topic modeling library to extract hierarchical topics from a collection of training requests. \n\nThe `hierarchical_topics` variable stores the result of applying the `hierarchical_topics()` method of the `topic_model` object to the `train_requs` input. This method likely performs some form of clustering or hierarchical analysis to group similar requests together into topics.\n\nThe `tree` variable stores the result of applying the `get_topic_tree()` method of the `topic_model` object to the `hierarchical_topics` input. This method likely converts the hierarchical topics into a tree structure to more easily visualize and understand the relationships between topics.\n\nFinally, the tree structure is printed to the console using the `print()` function. This will display the topic tree information in the notebook output.","date":"2023-10-26T01:53:26.829Z"}],"reply_to":"2023-10-26T01:53:26.820Z","sender_id":"chatgpt"}
{"date":"2023-10-26T02:07:37.619Z","event":"chat","history":[{"author_id":"d9218c0f-616b-453d-85a3-dcbe9ee8ddba","content":"<span class=\"user-mention\" account-id=chatgpt>@ChatGPT</span> help me fix my code.\n\n<details><summary>Context</summary>\n\n\nI ran a cell in a Jupyter notebook.\n\nI received the following error:\n\n```python\n---------------------------------------------------------------------------\nAttributeError                            Traceback (most recent call last)\nCell In[11], line 1\n----> 1 visualize_docs = topic_model.visualize_doucuments()\n\nAttributeError: 'BERTopic' object has no attribute 'visualize_doucuments'\n```\n\n\nMy Jupyter notebook using the Python 3 (Ubuntu Linux) kernel contains:\n\n```python\nvisualize_docs = topic_model.visualize_doucuments()\n```\n\n\n\n</details>","date":"2023-10-26T02:07:37.619Z"}],"sender_id":"d9218c0f-616b-453d-85a3-dcbe9ee8ddba"}
{"date":"2023-10-26T02:07:37.625Z","event":"chat","generating":false,"history":[{"author_id":"chatgpt","content":"The error message indicates that the `BERTopic` object does not have an attribute named `visualize_doucuments`. To fix this, you need to update the attribute name to `visualize_documents`. \n\nReplace the line of code in your Jupyter notebook from:\n\n```python\nvisualize_docs = topic_model.visualize_doucuments()\n```\n\nto:\n\n```python\nvisualize_docs = topic_model.visualize_documents()\n```\n\nAfter making this change, rerun the cell and the error should be resolved.","date":"2023-10-26T02:07:37.625Z"}],"reply_to":"2023-10-26T02:07:37.619Z","sender_id":"chatgpt"}
{"date":"2023-10-26T02:35:34.956Z","event":"chat","history":[{"author_id":"d9218c0f-616b-453d-85a3-dcbe9ee8ddba","content":"<span class=\"user-mention\" account-id=chatgpt>@ChatGPT</span> Explain the following Python 3 (Ubuntu Linux) code that is in a Jupyter notebook:\n\n<details>\n\n\n```python\nhierarchical_topics = topic_model.hierarchical_topics(train_requs)\ntree = topic_model.get_topic_tree(hierarchical_topics)\nprint(tree)\n```\n\n\n</details>","date":"2023-10-26T02:35:34.956Z"}],"sender_id":"d9218c0f-616b-453d-85a3-dcbe9ee8ddba"}
{"date":"2023-10-26T02:35:34.962Z","event":"chat","generating":false,"history":[{"author_id":"chatgpt","content":"This code uses a Python 3 library, `topic_model`, to perform topic modeling on a set of training requests (`train_requs`). \n\nThe `hierarchical_topics` variable is assigned the result of calling the `hierarchical_topics` method of the `topic_model` object on the `train_requs` data.\n\nThe `get_topic_tree` method of the `topic_model` object is then called on the `hierarchical_topics` to retrieve a hierarchical tree representation of the topics.\n\nFinally, the `print` function is used to display the tree.","date":"2023-10-26T02:35:34.962Z"}],"reply_to":"2023-10-26T02:35:34.956Z","sender_id":"chatgpt"}
{"date":"2023-10-26T02:35:56.882Z","event":"chat","history":[{"author_id":"d9218c0f-616b-453d-85a3-dcbe9ee8ddba","content":"is there anyway to export this visual","date":"2023-10-26T02:35:56.882Z"}],"reply_to":"2023-10-26T02:35:34.956Z","sender_id":"d9218c0f-616b-453d-85a3-dcbe9ee8ddba"}
{"date":"2023-10-26T02:35:56.886Z","event":"chat","generating":false,"history":[{"author_id":"chatgpt","content":"Yes, there are ways to export the visual representation of the topic tree. \n\nOne option is to save the tree as an image file. You can use libraries such as `matplotlib` or `pygraphviz` to generate a visual representation of the tree and save it as an image file (e.g., PNG, PDF, SVG).\n\nHere's an example using `matplotlib`:\n\n```python\nimport matplotlib.pyplot as plt\nimport networkx as nx\n\n# Assuming `tree` is the topic tree\nG = nx.DiGraph(tree)\npos = nx.nx_agraph.graphviz_layout(G, prog='dot')\n\nplt.figure(figsize=(10, 10))\nnx.draw(G, pos, with_labels=True)\nplt.savefig('topic_tree.png')\nplt.show()\n```\n\nThis code generates a visual representation of the topic tree using `matplotlib` and saves it as a PNG file named 'topic_tree.png'.\n\nAnother option is to export the tree as a text file, which can be useful for further analysis or sharing. You can write the tree structure to a text file using the `open` function and then iterate over the tree to write each node and its relationships in a desired format.\n\nHere's an example:\n\n```python\n# Assuming `tree` is the topic tree\nwith open('topic_tree.txt', 'w') as f:\n    for node in tree:\n        f.write(f'{node}\\n')\n        children = tree[node]\n        for child in children:\n            f.write(f'\\t{child}\\n')\n```\n\nThis code writes the topic tree structure to a text file named 'topic_tree.txt'. Each line represents a node, and an indented line represents its child node.","date":"2023-10-26T02:35:56.886Z"}],"reply_to":"2023-10-26T02:35:34.956Z","sender_id":"chatgpt"}
{"date":"2023-10-26T02:36:39.469Z","event":"chat","history":[{"author_id":"d9218c0f-616b-453d-85a3-dcbe9ee8ddba","content":"<span class=\"user-mention\" account-id=chatgpt>@ChatGPT</span> help me fix my code.\n\n<details><summary>Context</summary>\n\n\nI ran a cell in a Jupyter notebook.\n\nI received the following error:\n\n```python\n---------------------------------------------------------------------------\nImportError                               Traceback (most recent call last)\nCell In[20], line 5\n      2 tree = topic_model.get_topic_tree(hierarchical_topics)\n      3 print(tree)\n----> 5 import matplotlib.pyplot as plt\n      6 import networkx as nx\n      8 # Assuming `tree` is the topic tree\n\nFile ~/.local/lib/python3.10/site-packages/matplotlib/pyplot.py:66\n     63 from matplotlib import _docstring\n     64 from matplotlib.backend_bases import (\n     65     FigureCanvasBase, FigureManagerBase, MouseButton)\n---> 66 from matplotlib.figure import Figure, FigureBase, figaspect\n     67 from matplotlib.gridspec import GridSpec, SubplotSpec\n     68 from matplotlib import rcsetup, rcParamsDefault, rcParamsOrig\n\nFile ~/.local/lib/python3.10/site-packages/matplotlib/figure.py:43\n     40 import numpy as np\n     42 import matplotlib as mpl\n---> 43 from matplotlib import _blocking_input, backend_bases, _docstring, projections\n     44 from matplotlib.artist import (\n     45     Artist, allow_rasterization, _finalize_rasterization)\n     46 from matplotlib.backend_bases import (\n     47     DrawEvent, FigureCanvasBase, NonGuiException, MouseButton, _get_renderer)\n\nFile ~/.local/lib/python3.10/site-packages/matplotlib/projections/__init__.py:58\n     56 from .geo import AitoffAxes, HammerAxes, LambertAxes, MollweideAxes\n     57 from .polar import PolarAxes\n---> 58 from mpl_toolkits.mplot3d import Axes3D\n     61 class ProjectionRegistry:\n     62     \"\"\"A mapping of registered projection names to projection classes.\"\"\"\n\nFile /usr/lib/python3/dist-packages/mpl_toolkits/mplot3d/__init__.py:1\n----> 1 from .axes3d import Axes3D\n\nFile /usr/lib/python3/dist-packages/mpl_toolkits/mplot3d/axes3d.py:23\n     19 import textwrap\n     21 import numpy as np\n---> 23 from matplotlib import _api, cbook, docstring, _preprocess_data\n     24 import matplotlib.artist as martist\n     25 import matplotlib.axes as maxes\n\nImportError: cannot import name 'docstring' from 'matplotlib' (/projects/c7a1100d-10f9-4de1-b172-d38d7d09565f/.local/lib/python3.10/site-packages/matplotlib/__init__.py)\n```\n\n\nMy Jupyter notebook using the Python 3 (Ubuntu Linux) kernel contains:\n\n```python\nhierarchical_topics = topic_model.hierarchical_topics(train_requs)\ntree = topic_model.get_topic_tree(hierarchical_topics)\nprint(tree)\n\nimport matplotlib.pyplot as plt\nimport networkx as nx\n\n# Assuming `tree` is the topic tree\nG = nx.DiGraph(tree)\npos = nx.nx_agraph.graphviz_layout(G, prog='dot')\n\nplt.figure(figsize=(10, 10))\nnx.draw(G, pos, with_labels=True)\nplt.savefig('topic_tree.png')\nplt.show()\n```\n\n\n\n</details>","date":"2023-10-26T02:36:39.469Z"}],"sender_id":"d9218c0f-616b-453d-85a3-dcbe9ee8ddba"}
{"date":"2023-10-26T02:36:39.476Z","event":"chat","generating":false,"history":[{"author_id":"chatgpt","content":"The error message indicates that there is an issue with the `matplotlib` library. Specifically, it is unable to import the `docstring` module from `matplotlib`.\n\nTo fix this error, you can try the following steps:\n\n1. Update the `matplotlib` library to the latest version using the command: `!pip install --upgrade matplotlib`.\n\n2. Restart the kernel of your Jupyter notebook and run the code again.\n\nIf the issue persists, you may need to reinstall the `matplotlib` library using the command: `!pip uninstall matplotlib` and then `!pip install matplotlib`.\n\nIf none of the above steps work, it could be an issue with the installation of `matplotlib` or a conflict with other libraries. In this case, you can try creating a new virtual environment and installing only the necessary libraries for your project.\n\nLet me know if this helps resolve the issue or if you need further assistance.","date":"2023-10-26T02:36:39.476Z"}],"reply_to":"2023-10-26T02:36:39.469Z","sender_id":"chatgpt"}
{"date":"2023-10-26T02:56:08.771Z","event":"chat","history":[{"author_id":"d9218c0f-616b-453d-85a3-dcbe9ee8ddba","content":"<span class=\"user-mention\" account-id=chatgpt>@ChatGPT</span> help me fix my code.\n\n<details><summary>Context</summary>\n\n\nI ran a cell in a Jupyter notebook.\n\nI received the following error:\n\n```python\n---------------------------------------------------------------------------\nImportError                               Traceback (most recent call last)\nCell In[20], line 5\n      2 tree = topic_model.get_topic_tree(hierarchical_topics)\n      3 print(tree)\n----> 5 import matplotlib.pyplot as plt\n      6 import networkx as nx\n      8 # Assuming `tree` is the topic tree\n\nFile ~/.local/lib/python3.10/site-packages/matplotlib/pyplot.py:66\n     63 from matplotlib import _docstring\n     64 from matplotlib.backend_bases import (\n     65     FigureCanvasBase, FigureManagerBase, MouseButton)\n---> 66 from matplotlib.figure import Figure, FigureBase, figaspect\n     67 from matplotlib.gridspec import GridSpec, SubplotSpec\n     68 from matplotlib import rcsetup, rcParamsDefault, rcParamsOrig\n\nFile ~/.local/lib/python3.10/site-packages/matplotlib/figure.py:43\n     40 import numpy as np\n     42 import matplotlib as mpl\n---> 43 from matplotlib import _blocking_input, backend_bases, _docstring, projections\n     44 from matplotlib.artist import (\n     45     Artist, allow_rasterization, _finalize_rasterization)\n     46 from matplotlib.backend_bases import (\n     47     DrawEvent, FigureCanvasBase, NonGuiException, MouseButton, _get_renderer)\n\nFile ~/.local/lib/python3.10/site-packages/matplotlib/projections/__init__.py:58\n     56 from .geo import AitoffAxes, HammerAxes, LambertAxes, MollweideAxes\n     57 from .polar import PolarAxes\n---> 58 from mpl_toolkits.mplot3d import Axes3D\n     61 class ProjectionRegistry:\n     62     \"\"\"A mapping of registered projection names to projection classes.\"\"\"\n\nFile /usr/lib/python3/dist-packages/mpl_toolkits/mplot3d/__init__.py:1\n----> 1 from .axes3d import Axes3D\n\nFile /usr/lib/python3/dist-packages/mpl_toolkits/mplot3d/axes3d.py:23\n     19 import textwrap\n     21 import numpy as np\n---> 23 from matplotlib import _api, cbook, docstring, _preprocess_data\n     24 import matplotlib.artist as martist\n     25 import matplotlib.axes as maxes\n\nImportError: cannot import name 'docstring' from 'matplotlib' (/projects/c7a1100d-10f9-4de1-b172-d38d7d09565f/.local/lib/python3.10/site-packages/matplotlib/__init__.py)\n```\n\n\nMy Jupyter notebook using the Python 3 (Ubuntu Linux) kernel contains:\n\n```python\nhierarchical_topics = topic_model.hierarchical_topics(train_requs)\ntree = topic_model.get_topic_tree(hierarchical_topics)\nprint(tree)\n\nimport matplotlib.pyplot as plt\nimport networkx as nx\n\n# Assuming `tree` is the topic tree\nG = nx.DiGraph(tree)\npos = nx.nx_agraph.graphviz_layout(G, prog='dot')\n\nplt.figure(figsize=(10, 10))\nnx.draw(G, pos, with_labels=True)\nplt.savefig('topic_tree.png')\nplt.show()\n```\n\n\n\n</details>","date":"2023-10-26T02:56:08.771Z"}],"sender_id":"d9218c0f-616b-453d-85a3-dcbe9ee8ddba"}
{"date":"2023-10-26T02:56:08.777Z","event":"chat","generating":true,"history":[{"author_id":"chatgpt","content":"It looks like there is an `ImportError` related to the `docstring` module in `matplotlib`. This error can occur if there is a version compatibility issue or if the module is missing or corrupted.\n\nHere are a few steps you can try to fix the issue:\n\n1. Restart the kernel: Sometimes, restarting the kernel can resolve import issues. You can do this by clicking on the \"Kernel\" menu and selecting \"Restart Kernel\".\n\n2. Update `matplotlib`: It's possible that updating `matplotlib` to the latest version can resolve the issue. You can do this by\n\n<span style='color:#b71c1c'>disconnect</span>\n\n---\n\nOpenAI [status](https://status.openai.com) and [downdetector](https://downdetector.com/status/openai).","date":"2023-10-26T02:56:08.777Z"}],"reply_to":"2023-10-26T02:56:08.771Z","sender_id":"chatgpt"}
{"date":"2023-10-26T02:58:44.180Z","event":"chat","history":[{"author_id":"d9218c0f-616b-453d-85a3-dcbe9ee8ddba","content":"<span class=\"user-mention\" account-id=chatgpt>@ChatGPT</span> help me fix my code.\n\n<details><summary>Context</summary>\n\n\nI ran a cell in a Jupyter notebook.\n\nI received the following error:\n\n```python\n---------------------------------------------------------------------------\nImportError                               Traceback (most recent call last)\nCell In[7], line 5\n      2 tree = topic_model.get_topic_tree(hierarchical_topics)\n      3 print(tree)\n----> 5 import matplotlib.pyplot as plt\n      6 import networkx as nx\n      8 # Assuming `tree` is the topic tree\n\nFile ~/.local/lib/python3.10/site-packages/matplotlib/pyplot.py:66\n     63 from matplotlib import _docstring\n     64 from matplotlib.backend_bases import (\n     65     FigureCanvasBase, FigureManagerBase, MouseButton)\n---> 66 from matplotlib.figure import Figure, FigureBase, figaspect\n     67 from matplotlib.gridspec import GridSpec, SubplotSpec\n     68 from matplotlib import rcsetup, rcParamsDefault, rcParamsOrig\n\nFile ~/.local/lib/python3.10/site-packages/matplotlib/figure.py:43\n     40 import numpy as np\n     42 import matplotlib as mpl\n---> 43 from matplotlib import _blocking_input, backend_bases, _docstring, projections\n     44 from matplotlib.artist import (\n     45     Artist, allow_rasterization, _finalize_rasterization)\n     46 from matplotlib.backend_bases import (\n     47     DrawEvent, FigureCanvasBase, NonGuiException, MouseButton, _get_renderer)\n\nFile ~/.local/lib/python3.10/site-packages/matplotlib/projections/__init__.py:58\n     56 from .geo import AitoffAxes, HammerAxes, LambertAxes, MollweideAxes\n     57 from .polar import PolarAxes\n---> 58 from mpl_toolkits.mplot3d import Axes3D\n     61 class ProjectionRegistry:\n     62     \"\"\"A mapping of registered projection names to projection classes.\"\"\"\n\nFile /usr/lib/python3/dist-packages/mpl_toolkits/mplot3d/__init__.py:1\n----> 1 from .axes3d import Axes3D\n\nFile /usr/lib/python3/dist-packages/mpl_toolkits/mplot3d/axes3d.py:23\n     19 import textwrap\n     21 import numpy as np\n---> 23 from matplotlib import _api, cbook, docstring, _preprocess_data\n     24 import matplotlib.artist as martist\n     25 import matplotlib.axes as maxes\n\nImportError: cannot import name 'docstring' from 'matplotlib' (/projects/c7a1100d-10f9-4de1-b172-d38d7d09565f/.local/lib/python3.10/site-packages/matplotlib/__init__.py)\n```\n\n\nMy Jupyter notebook using the Python 3 (Ubuntu Linux) kernel contains:\n\n```python\nhierarchical_topics = topic_model.hierarchical_topics(train_requs)\ntree = topic_model.get_topic_tree(hierarchical_topics)\nprint(tree)\n\nimport matplotlib.pyplot as plt\nimport networkx as nx\n\n# Assuming `tree` is the topic tree\nG = nx.DiGraph(tree)\npos = nx.nx_agraph.graphviz_layout(G, prog='dot')\n\nplt.figure(figsize=(10, 10))\nnx.draw(G, pos, with_labels=True)\nplt.savefig('topic_tree.png')\nplt.show()\n```\n\n\n\n</details>","date":"2023-10-26T02:58:44.180Z"}],"sender_id":"d9218c0f-616b-453d-85a3-dcbe9ee8ddba"}
{"date":"2023-10-26T02:58:44.195Z","event":"chat","generating":false,"history":[{"author_id":"chatgpt","content":"It looks like the error is caused by an import error related to the `docstring` module in the `matplotlib` package. To fix this issue, you can try the following steps:\n\n1. Update the `matplotlib` package by running the following command:\n\n```\n!pip install --upgrade matplotlib\n```\n\n2. Restart the Jupyter kernel to ensure the updated package is used.\n\nYou can do this by clicking on the \"Kernel\" menu and selecting \"Restart Kernel\".\n\n3. After the kernel restarts, rerun the cell to see if the error is resolved.\n\nIf the error persists, you can try reinstalling the `matplotlib` package using the following command:\n\n```\n!pip uninstall matplotlib\n!pip install matplotlib\n```\n\nThen restart the kernel and rerun the cell again.\n\nI hope this helps! Let me know if you have any further questions.","date":"2023-10-26T02:58:44.195Z"}],"reply_to":"2023-10-26T02:58:44.180Z","sender_id":"chatgpt"}
{"date":"2023-10-26T05:33:02.178Z","event":"chat","history":[{"author_id":"d9218c0f-616b-453d-85a3-dcbe9ee8ddba","content":"<span class=\"user-mention\" account-id=chatgpt>@ChatGPT</span> Explain the following Python 3 (Ubuntu Linux) code that is in a Jupyter notebook:\n\n<details>\n\n\n```python\ntopic_embeddings = topic_model.get_topic_info()\n\n# Print the topic embeddings\nprint(topic_embeddings)\n```\n\n\n</details>","date":"2023-10-26T05:33:02.178Z"}],"sender_id":"d9218c0f-616b-453d-85a3-dcbe9ee8ddba"}
{"date":"2023-10-26T05:33:02.184Z","event":"chat","generating":false,"history":[{"author_id":"chatgpt","content":"The code retrieves the topic embeddings from a topic model and then prints the topic embeddings.","date":"2023-10-26T05:33:02.184Z"}],"reply_to":"2023-10-26T05:33:02.178Z","sender_id":"chatgpt"}
{"date":"2023-10-26T05:33:17.558Z","event":"chat","history":[{"author_id":"d9218c0f-616b-453d-85a3-dcbe9ee8ddba","content":"what if i want to save this to a csv file","date":"2023-10-26T05:33:17.558Z"}],"reply_to":"2023-10-26T05:33:02.178Z","sender_id":"d9218c0f-616b-453d-85a3-dcbe9ee8ddba"}
{"date":"2023-10-26T05:33:17.564Z","event":"chat","generating":false,"history":[{"author_id":"chatgpt","content":"To save the topic embeddings to a CSV file, you can use the `pandas` library in Python. Here's an example code snippet that saves the topic embeddings to a CSV file:\n\n```python\nimport pandas as pd\n\ntopic_embeddings = topic_model.get_topic_info()\n\n# Create a DataFrame from the topic embeddings\ndf = pd.DataFrame(topic_embeddings)\n\n# Save the DataFrame to a CSV file\ndf.to_csv('topic_embeddings.csv', index=False)\n```\n\nIn this code, we first import the `pandas` library. Then, we retrieve the topic embeddings using `topic_model.get_topic_info()` and store them in the `topic_embeddings` variable.\n\nNext, we create a DataFrame from the topic embeddings using `pd.DataFrame(topic_embeddings)`. A DataFrame is a tabular data structure provided by the `pandas` library.\n\nFinally, we save the DataFrame to a CSV file named \"topic_embeddings.csv\" using `df.to_csv('topic_embeddings.csv', index=False)`. The `index=False` argument specifies that we don't want to include the row index in the CSV file.","date":"2023-10-26T05:33:17.564Z"}],"reply_to":"2023-10-26T05:33:02.178Z","sender_id":"chatgpt"}